Workbook

Sheet 사용설명
B8: 1. Main 탭 - 회사정보 입력, 사원명부 입력
B29: 2. 휴가대장 관리용 탭
C30: 1) 연차일수, 연차수 조정 입력
D31: -> 연차일수 : 연도별로 연차일수를 계산하며, 전기 이월분은 연차수조정을 통해 계산함. // 연차수조정 : 전기 이월된 연차 or 미리 사용한 연차를 조정
C32: 2) 연차 사용내역 입력
D33: -> 몇일에 사용하였는지 입력필요 // 반드시 " , " (콤마)를 사용하여 일수를 구분해야 함.
C34: 3) 반차 합계일수 입력
D35: (--> ex) 반차 3번 사용시 = 1.5 입력, 반차 1번 사용시 = 0.5 입력)
B56: 3. 원본엑셀은 보관 잘 해두시길 바라며, 엑셀을 복사하여 연도별로 사용하시는걸 추천드립니다.
C57: * 엑셀수식이 깨질 수 있으므로 원본엑셀을 꼭 저장해두시길 바랍니다.

Sheet 사원명부
A4: =J5&" 사원명부" -> ㈜한슬 사원명부 | I4: 회사정보 입력란
I5: 회사명 | J5: ㈜한슬
A6: 사원번호 | B6: 직 책 | C6: 부 서 | D6: 성 명 | E6: 입 사 일 | F6: 비 고 | I6: 대표자 | J6: 정영수
I7: 연락처 | J7: 536267805
A8: 1 | B8: 이사 | C8: 개발1팀 | D8: 양승진 | E8: 1990-09-01 | I8: 소재지 | J8: 대구 달서구 성서공단북로 305
A9: 2 | B9: 이사 | C9: 개발2팀 | D9: 최창열 | E9: 2000-10-01
A10: 3 | B10: 차장 | C10: CAD실 | D10: 김은정 | E10: 2002-07-26
A11: 4 | B11: 실장 | C11: CAD실 | D11: 이정화 | E11: 2003-01-02
A12: 5 | B12: 부장 | C12: 개발1팀 | D12: 하치복 | E12: 2004-03-15
A13: 6 | B13: 부장 | C13: 개발2팀 | D13: 권혁진 | E13: 2004-11-10
A14: 7 | B14: 과장 | C14: 개발1팀 | D14: 김경태 | E14: 2013-04-26
A15: 8 | B15: 연구소장 | C15: 개발2팀 | D15: 조근일 | E15: 2013-11-04
A16: 9 | B16: 과장 | C16: 개발1팀 | D16: 이재형 | E16: 2015-03-16
A17: 10 | B17: 과장 | C17: CAD실 | D17: 임소연 | E17: 2006-12-01
A18: 11 | B18: 대리 | C18: CAD실 | D18: 김지혜 | E18: 2018-02-06
A19: 12 | B19: 주임연구원 | C19: 부설연구소 | D19: 정승후 | E19: 2018-07-02
A20: 13 | B20: 대리 | C20: CAD실 | D20: 나유성 | E20: 2018-09-27
... A31: 24 | B31: 사원 | C31: 개발1팀 | D31: 백현덕 | E31: 2023-03-06
A32: 25 | B32: 사원 | C32: 개발1팀 | D32: 이종근 | E32: 45586
A33: 26 | B33: 사원 | C33: 경영팀 | D33: 이채령 | E33: 45663
A34: 27
A35: 28 | B35: 사원 | C35: 개발1팀 | D35: 최창진 | E35: 45694
A36: 29
A37: 30
A38: 31
A39: 32
A40: 33
A41: 34
A42: 35
A43: 36
A44: 37
A45: 38
A46: 39
A47: 40
... A107: 100

Sheet 휴가대장 관리용
A4: 연차휴가 관리대장
B6: 직책 | C6: 성 명 | D6: 입사일 | E6: 연차시작일 | F6: 연차일수 | G6: 연차수 조정 | H6: 사용가능 연차 | I6: (-)사용연차 | J6: (=)남은연차 | K6: 월별 휴가 사용내역 | W6: 사용합계 | X6: 반차일수 합계 | Y6: 비 고
K7: 01월 | L7: 02월 | M7: 03월 | N7: 04월 | O7: 05월 | P7: 06월 | Q7: 07월 | R7: 08월 | S7: 09월 | T7: 10월 | U7: 11월 | V7: 12월
A8: 1 | B8: =사원명부!B8 -> 이사 | C8: =사원명부!D8 -> 양승진 | D8: =IF(B8=0,"-",사원명부!E8) -> 1990-09-01 | E8: =IF(B8=0,"-",D8+1) -> 33118 | F8: 25 | H8: =IFERROR(F8+G8,"") -> 25 | I8: =W8 -> 10.5 | J8: =IFERROR(F8+G8-I8,"") -> 14.5 | M8: 27일(오전반차) | N8: 2일, 15일(오후반차) | O8: 02일 | Q8: 15일(오후반차), 18일,21일, 22일,23일,24일,25일 | R8: 1일 | W8: =LEN(K8)-LEN(SUBSTITUTE(K8,",",""))+1-COUNTBLANK(K8)+LEN(L8)-LEN(SUBSTITUTE(L8,",",""))+1-COUNTBLANK(L8)+LEN(M8)-LEN(SUBSTITUTE(M8,",",""))+1-COUNTBLANK(M8)+LEN(N8)-LEN(SUBSTITUTE(N8,",",""))+1-COUNTBLANK(N8)+LEN(O8)-LEN(SUBSTITUTE(O8,",",""))+1-COUNTBLANK(O8)+LEN(P8)-LEN(SUBSTITUTE(P8,",",""))+1-COUNTBLANK(P8)+LEN(Q8)-LEN(SUBSTITUTE(Q8,",",""))+1-COUNTBLANK(Q8)+LEN(R8)-LEN(SUBSTITUTE(R8,",",""))+1-COUNTBLANK(R8)+LEN(S8)-LEN(SUBSTITUTE(S8,",",""))+1-COUNTBLANK(S8)+LEN(T8)-LEN(SUBSTITUTE(T8,",",""))+1-COUNTBLANK(T8)+LEN(U8)-LEN(SUBSTITUTE(U8,",",""))+1-COUNTBLANK(U8)+LEN(V8)-LEN(SUBSTITUTE(V8,",",""))+1-COUNTBLANK(V8)-X8 -> 10.5 | X8: 1.5
A9: 2 | B9: =사원명부!B9 -> 이사 | C9: =사원명부!D9 -> 최창열 | D9: =IF(B9=0,"-",사원명부!E9) -> 2000-10-01 | E9: =IF(B9=0,"-",D9+1) -> 36801 | F9: 25 | H9: =IFERROR(F9+G9,"") -> 25 | I9: =W9 -> 10 | J9: =IFERROR(F9+G9-I9,"") -> 15 | L9: 24일(오후반차) | M9: 28일(오후반차) | N9: 29일,30일 | O9: 28일 | P9: 13일(오후반차), 16일,18일, 20일(오후반차) | Q9: 08(오후반차), 09일 | R9: 5일(오후반차), 20일 | W9: =LEN(K9)-LEN(SUBSTITUTE(K9,",",""))+1-COUNTBLANK(K9)+LEN(L9)-LEN(SUBSTITUTE(L9,",",""))+1-COUNTBLANK(L9)+LEN(M9)-LEN(SUBSTITUTE(M9,",",""))+1-COUNTBLANK(M9)+LEN(N9)-LEN(SUBSTITUTE(N9,",",""))+1-COUNTBLANK(N9)+LEN(O9)-LEN(SUBSTITUTE(O9,",",""))+1-COUNTBLANK(O9)+LEN(P9)-LEN(SUBSTITUTE(P9,",",""))+1-COUNTBLANK(P9)+LEN(Q9)-LEN(SUBSTITUTE(Q9,",",""))+1-COUNTBLANK(Q9)+LEN(R9)-LEN(SUBSTITUTE(R9,",",""))+1-COUNTBLANK(R9)+LEN(S9)-LEN(SUBSTITUTE(S9,",",""))+1-COUNTBLANK(S9)+LEN(T9)-LEN(SUBSTITUTE(T9,",",""))+1-COUNTBLANK(T9)+LEN(U9)-LEN(SUBSTITUTE(U9,",",""))+1-COUNTBLANK(U9)+LEN(V9)-LEN(SUBSTITUTE(V9,",",""))+1-COUNTBLANK(V9)-X9 -> 10 | X9: 3
A10: 3 | B10: =사원명부!B10 -> 차장 | C10: =사원명부!D10 -> 김은정 | D10: =IF(B10=0,"-",사원명부!E10) -> 2002-07-26 | E10: =IF(B10=0,"-",D10+1) -> 37464 | F10: 25 | H10: =IFERROR(F10+G10,"") -> 25 | I10: =W10 -> 14 | J10: =IFERROR(F10+G10-I10,"") -> 11 | K10: 22일 | L10: 20일,27,28 | M10: 05(오후반차),12 | N10: 23일, 28일(오후반차) | P10: 05일(오후반차) | Q10: 07일,16일, 17일(오후반차), 30일,31일 | R10: 1일, 14일(오전반차) | W10: =LEN(K10)-LEN(SUBSTITUTE(K10,",",""))+1-COUNTBLANK(K10)+LEN(L10)-LEN(SUBSTITUTE(L10,",",""))+1-COUNTBLANK(L10)+LEN(M10)-LEN(SUBSTITUTE(M10,",",""))+1-COUNTBLANK(M10)+LEN(N10)-LEN(SUBSTITUTE(N10,",",""))+1-COUNTBLANK(N10)+LEN(O10)-LEN(SUBSTITUTE(O10,",",""))+1-COUNTBLANK(O10)+LEN(P10)-LEN(SUBSTITUTE(P10,",",""))+1-COUNTBLANK(P10)+LEN(Q10)-LEN(SUBSTITUTE(Q10,",",""))+1-COUNTBLANK(Q10)+LEN(R10)-LEN(SUBSTITUTE(R10,",",""))+1-COUNTBLANK(R10)+LEN(S10)-LEN(SUBSTITUTE(S10,",",""))+1-COUNTBLANK(S10)+LEN(T10)-LEN(SUBSTITUTE(T10,",",""))+1-COUNTBLANK(T10)+LEN(U10)-LEN(SUBSTITUTE(U10,",",""))+1-COUNTBLANK(U10)+LEN(V10)-LEN(SUBSTITUTE(V10,",",""))+1-COUNTBLANK(V10)-X10 -> 14 | X10: 2
A11: 4 | B11: =사원명부!B11 -> 실장 | C11: =사원명부!D11 -> 이정화 | D11: =IF(B11=0,"-",사원명부!E11) -> 2003-01-02 | E11: =IF(B11=0,"-",D11+1) -> 37624 | F11: 25 | H11: =IFERROR(F11+G11,"") -> 25 | I11: =W11 -> 15.5 | J11: =IFERROR(F11+G11-I11,"") -> 9.5 | K11: 17일(오후반차), 31일(오후반차) | L11: 7일(오후반차), 21일,28일 | M11: 14(오후반차) | N11: 2일,25일 | O11: 2일, 29일(오후반차) | P11: 20일 | Q11: 18일,21일, 22일,23일,24일,25일 | R11: 1일 | W11: =LEN(K11)-LEN(SUBSTITUTE(K11,",",""))+1-COUNTBLANK(K11)+LEN(L11)-LEN(SUBSTITUTE(L11,",",""))+1-COUNTBLANK(L11)+LEN(M11)-LEN(SUBSTITUTE(M11,",",""))+1-COUNTBLANK(M11)+LEN(N11)-LEN(SUBSTITUTE(N11,",",""))+1-COUNTBLANK(N11)+LEN(O11)-LEN(SUBSTITUTE(O11,",",""))+1-COUNTBLANK(O11)+LEN(P11)-LEN(SUBSTITUTE(P11,",",""))+1-COUNTBLANK(P11)+LEN(Q11)-LEN(SUBSTITUTE(Q11,",",""))+1-COUNTBLANK(Q11)+LEN(R11)-LEN(SUBSTITUTE(R11,",",""))+1-COUNTBLANK(R11)+LEN(S11)-LEN(SUBSTITUTE(S11,",",""))+1-COUNTBLANK(S11)+LEN(T11)-LEN(SUBSTITUTE(T11,",",""))+1-COUNTBLANK(T11)+LEN(U11)-LEN(SUBSTITUTE(U11,",",""))+1-COUNTBLANK(U11)+LEN(V11)-LEN(SUBSTITUTE(V11,",",""))+1-COUNTBLANK(V11)-X11 -> 15.5 | X11: 2.5
A12: 5 | B12: =사원명부!B12 -> 부장 | C12: =사원명부!D12 -> 하치복 | D12: =IF(B12=0,"-",사원명부!E12) -> 2004-03-15 | E12: =IF(B12=0,"-",D12+1) -> 38062 | F12: 24 | G12: 1 | H12: =IFERROR(F12+G12,"") -> 25 | I12: =W12 -> 6.5 | J12: =IFERROR(F12+G12-I12,"") -> 18.5 | K12: 10일 | L12: 21일 | M12: 28 | N12: 18일 | Q12: 11일(오후반차), 31일 | R12: 1일 | W12: =LEN(K12)-LEN(SUBSTITUTE(K12,",",""))+1-COUNTBLANK(K12)+LEN(L12)-LEN(SUBSTITUTE(L12,",",""))+1-COUNTBLANK(L12)+LEN(M12)-LEN(SUBSTITUTE(M12,",",""))+1-COUNTBLANK(M12)+LEN(N12)-LEN(SUBSTITUTE(N12,",",""))+1-COUNTBLANK(N12)+LEN(O12)-LEN(SUBSTITUTE(O12,",",""))+1-COUNTBLANK(O12)+LEN(P12)-LEN(SUBSTITUTE(P12,",",""))+1-COUNTBLANK(P12)+LEN(Q12)-LEN(SUBSTITUTE(Q12,",",""))+1-COUNTBLANK(Q12)+LEN(R12)-LEN(SUBSTITUTE(R12,",",""))+1-COUNTBLANK(R12)+LEN(S12)-LEN(SUBSTITUTE(S12,",",""))+1-COUNTBLANK(S12)+LEN(T12)-LEN(SUBSTITUTE(T12,",",""))+1-COUNTBLANK(T12)+LEN(U12)-LEN(SUBSTITUTE(U12,",",""))+1-COUNTBLANK(U12)+LEN(V12)-LEN(SUBSTITUTE(V12,",",""))+1-COUNTBLANK(V12)-X12 -> 6.5 | X12: 0.5
A13: 6 | B13: =사원명부!B13 -> 부장 | C13: =사원명부!D13 -> 권혁진 | D13: =IF(B13=0,"-",사원명부!E13) -> 2004-11-10 | E13: =IF(B13=0,"-",D13+1) -> 38302 | F13: 24 | G13: 1 | H13: =IFERROR(F13+G13,"") -> 25 | I13: =W13 -> 3 | J13: =IFERROR(F13+G13-I13,"") -> 22 | K13: 3일(오후반자), 20일,31일 | L13: 7일(오후반차) | W13: =LEN(K13)-LEN(SUBSTITUTE(K13,",",""))+1-COUNTBLANK(K13)+LEN(L13)-LEN(SUBSTITUTE(L13,",",""))+1-COUNTBLANK(L13)+LEN(M13)-LEN(SUBSTITUTE(M13,",",""))+1-COUNTBLANK(M13)+LEN(N13)-LEN(SUBSTITUTE(N13,",",""))+1-COUNTBLANK(N13)+LEN(O13)-LEN(SUBSTITUTE(O13,",",""))+1-COUNTBLANK(O13)+LEN(P13)-LEN(SUBSTITUTE(P13,",",""))+1-COUNTBLANK(P13)+LEN(Q13)-LEN(SUBSTITUTE(Q13,",",""))+1-COUNTBLANK(Q13)+LEN(R13)-LEN(SUBSTITUTE(R13,",",""))+1-COUNTBLANK(R13)+LEN(S13)-LEN(SUBSTITUTE(S13,",",""))+1-COUNTBLANK(S13)+LEN(T13)-LEN(SUBSTITUTE(T13,",",""))+1-COUNTBLANK(T13)+LEN(U13)-LEN(SUBSTITUTE(U13,",",""))+1-COUNTBLANK(U13)+LEN(V13)-LEN(SUBSTITUTE(V13,",",""))+1-COUNTBLANK(V13)-X13 -> 3 | X13: 1
A14: 7 | B14: =사원명부!B14 -> 과장 | C14: =사원명부!D14 -> 김경태 | D14: =IF(B14=0,"-",사원명부!E14) -> 2013-04-26 | E14: =IF(B14=0,"-",D14+1) -> 41391 | F14: 20 | H14: =IFERROR(F14+G14,"") -> 20 | I14: =W14 -> 11 | J14: =IFERROR(F14+G14-I14,"") -> 9 | K14: 10일(오후반차), 31일 | L14: 11일,12일,13일,19일 | M14: 4일 | N14: 7일, 23일(오후반차) | Q14: 11일,31일 | R14: 1일 | W14: =LEN(K14)-LEN(SUBSTITUTE(K14,",",""))+1-COUNTBLANK(K14)+LEN(L14)-LEN(SUBSTITUTE(L14,",",""))+1-COUNTBLANK(L14)+LEN(M14)-LEN(SUBSTITUTE(M14,",",""))+1-COUNTBLANK(M14)+LEN(N14)-LEN(SUBSTITUTE(N14,",",""))+1-COUNTBLANK(N14)+LEN(O14)-LEN(SUBSTITUTE(O14,",",""))+1-COUNTBLANK(O14)+LEN(P14)-LEN(SUBSTITUTE(P14,",",""))+1-COUNTBLANK(P14)+LEN(Q14)-LEN(SUBSTITUTE(Q14,",",""))+1-COUNTBLANK(Q14)+LEN(R14)-LEN(SUBSTITUTE(R14,",",""))+1-COUNTBLANK(R14)+LEN(S14)-LEN(SUBSTITUTE(S14,",",""))+1-COUNTBLANK(S14)+LEN(T14)-LEN(SUBSTITUTE(T14,",",""))+1-COUNTBLANK(T14)+LEN(U14)-LEN(SUBSTITUTE(U14,",",""))+1-COUNTBLANK(U14)+LEN(V14)-LEN(SUBSTITUTE(V14,",",""))+1-COUNTBLANK(V14)-X14 -> 11 | X14: 1
A15: 8 | B15: =사원명부!B15 -> 연구소장 | C15: =사원명부!D15 -> 조근일 | D15: =IF(B15=0,"-",사원명부!E15) -> 2013-11-04 | E15: =IF(B15=0,"-",D15+1) -> 41583 | F15: 20 | H15: =IFERROR(F15+G15,"") -> 20 | I15: =W15 -> 6.5 | J15: =IFERROR(F15+G15-I15,"") -> 13.5 | K15: 2일 | L15: 12일,13일,14일 | M15: 27(오전반차) | N15: 8일(오전반차) | O15: 28일(오후반차) | Q15: 2일(오후반차) | R15: 1일(오후반차) | W15: =LEN(K15)-LEN(SUBSTITUTE(K15,",",""))+1-COUNTBLANK(K15)+LEN(L15)-LEN(SUBSTITUTE(L15,",",""))+1-COUNTBLANK(L15)+LEN(M15)-LEN(SUBSTITUTE(M15,",",""))+1-COUNTBLANK(M15)+LEN(N15)-LEN(SUBSTITUTE(N15,",",""))+1-COUNTBLANK(N15)+LEN(O15)-LEN(SUBSTITUTE(O15,",",""))+1-COUNTBLANK(O15)+LEN(P15)-LEN(SUBSTITUTE(P15,",",""))+1-COUNTBLANK(P15)+LEN(Q15)-LEN(SUBSTITUTE(Q15,",",""))+1-COUNTBLANK(Q15)+LEN(R15)-LEN(SUBSTITUTE(R15,",",""))+1-COUNTBLANK(R15)+LEN(S15)-LEN(SUBSTITUTE(S15,",",""))+1-COUNTBLANK(S15)+LEN(T15)-LEN(SUBSTITUTE(T15,",",""))+1-COUNTBLANK(T15)+LEN(U15)-LEN(SUBSTITUTE(U15,",",""))+1-COUNTBLANK(U15)+LEN(V15)-LEN(SUBSTITUTE(V15,",",""))+1-COUNTBLANK(V15)-X15 -> 6.5 | X15: 2.5
A16: 9 | B16: =사원명부!B16 -> 과장 | C16: =사원명부!D16 -> 이재형 | D16: =IF(B16=0,"-",사원명부!E16) -> 2015-03-16 | E16: =IF(B16=0,"-",D16+1) -> 42080 | F16: 19 | H16: =IFERROR(F16+G16,"") -> 19 | I16: =W16 -> 9.5 | J16: =IFERROR(F16+G16-I16,"") -> 9.5 | K16: 9일(오전반차),14일, 20일(오후반차) | L16: 28일 | M16: 24(오후반차) | O16: 2일 | P16: 9일(오전반차), 16일(오후반차), 30일(오전) | Q16: 7일, 18일(오후반차) | R16: 12일,13일 | W16: =LEN(K16)-LEN(SUBSTITUTE(K16,",",""))+1-COUNTBLANK(K16)+LEN(L16)-LEN(SUBSTITUTE(L16,",",""))+1-COUNTBLANK(L16)+LEN(M16)-LEN(SUBSTITUTE(M16,",",""))+1-COUNTBLANK(M16)+LEN(N16)-LEN(SUBSTITUTE(N16,",",""))+1-COUNTBLANK(N16)+LEN(O16)-LEN(SUBSTITUTE(O16,",",""))+1-COUNTBLANK(O16)+LEN(P16)-LEN(SUBSTITUTE(P16,",",""))+1-COUNTBLANK(P16)+LEN(Q16)-LEN(SUBSTITUTE(Q16,",",""))+1-COUNTBLANK(Q16)+LEN(R16)-LEN(SUBSTITUTE(R16,",",""))+1-COUNTBLANK(R16)+LEN(S16)-LEN(SUBSTITUTE(S16,",",""))+1-COUNTBLANK(S16)+LEN(T16)-LEN(SUBSTITUTE(T16,",",""))+1-COUNTBLANK(T16)+LEN(U16)-LEN(SUBSTITUTE(U16,",",""))+1-COUNTBLANK(U16)+LEN(V16)-LEN(SUBSTITUTE(V16,",",""))+1-COUNTBLANK(V16)-X16 -> 9.5 | X16: 3.5
A17: 10 | B17: =사원명부!B17 -> 과장 | C17: =사원명부!D17 -> 임소연 | D17: =IF(B17=0,"-",사원명부!E17) -> 2006-12-01 | E17: =IF(B17=0,"-",D17+1) -> 39053 | F17: 23 | H17: =IFERROR(F17+G17,"") -> 23 | I17: =W17 -> 13.5 | J17: =IFERROR(F17+G17-I17,"") -> 9.5 | K17: 2일,8일(오전반차), 22일,31일 | L17: 28일 | M17: 4,25(오후반차) | N17: 17일,18일23일, 30일(오후반차) | O17: 27일(오전반차) | P17: 18일(오후반차) | Q17: 30일,31일 | R17: 1일,4일 | W17: =LEN(K17)-LEN(SUBSTITUTE(K17,",",""))+1-COUNTBLANK(K17)+LEN(L17)-LEN(SUBSTITUTE(L17,",",""))+1-COUNTBLANK(L17)+LEN(M17)-LEN(SUBSTITUTE(M17,",",""))+1-COUNTBLANK(M17)+LEN(N17)-LEN(SUBSTITUTE(N17,",",""))+1-COUNTBLANK(N17)+LEN(O17)-LEN(SUBSTITUTE(O17,",",""))+1-COUNTBLANK(O17)+LEN(P17)-LEN(SUBSTITUTE(P17,",",""))+1-COUNTBLANK(P17)+LEN(Q17)-LEN(SUBSTITUTE(Q17,",",""))+1-COUNTBLANK(Q17)+LEN(R17)-LEN(SUBSTITUTE(R17,",",""))+1-COUNTBLANK(R17)+LEN(S17)-LEN(SUBSTITUTE(S17,",",""))+1-COUNTBLANK(S17)+LEN(T17)-LEN(SUBSTITUTE(T17,",",""))+1-COUNTBLANK(T17)+LEN(U17)-LEN(SUBSTITUTE(U17,",",""))+1-COUNTBLANK(U17)+LEN(V17)-LEN(SUBSTITUTE(V17,",",""))+1-COUNTBLANK(V17)-X17 -> 13.5 | X17: 2.5
A18: 11 | B18: =사원명부!B18 -> 대리 | C18: =사원명부!D18 -> 김지혜 | D18: =IF(B18=0,"-",사원명부!E18) -> 2018-02-06 | E18: =IF(B18=0,"-",D18+1) -> 43138 | F18: 17 | H18: =IFERROR(F18+G18,"") -> 17 | I18: =W18 -> 7.5 | J18: =IFERROR(F18+G18-I18,"") -> 9.5 | K18: 31일 | L18: 21일,28일 | P18: 18일(오후) | Q18: 3일(오후반차), 4일, 17일(오후반차), 28일,29일 | W18: =LEN(K18)-LEN(SUBSTITUTE(K18,",",""))+1-COUNTBLANK(K18)+LEN(L18)-LEN(SUBSTITUTE(L18,",",""))+1-COUNTBLANK(L18)+LEN(M18)-LEN(SUBSTITUTE(M18,",",""))+1-COUNTBLANK(M18)+LEN(N18)-LEN(SUBSTITUTE(N18,",",""))+1-COUNTBLANK(N18)+LEN(O18)-LEN(SUBSTITUTE(O18,",",""))+1-COUNTBLANK(O18)+LEN(P18)-LEN(SUBSTITUTE(P18,",",""))+1-COUNTBLANK(P18)+LEN(Q18)-LEN(SUBSTITUTE(Q18,",",""))+1-COUNTBLANK(Q18)+LEN(R18)-LEN(SUBSTITUTE(R18,",",""))+1-COUNTBLANK(R18)+LEN(S18)-LEN(SUBSTITUTE(S18,",",""))+1-COUNTBLANK(S18)+LEN(T18)-LEN(SUBSTITUTE(T18,",",""))+1-COUNTBLANK(T18)+LEN(U18)-LEN(SUBSTITUTE(U18,",",""))+1-COUNTBLANK(U18)+LEN(V18)-LEN(SUBSTITUTE(V18,",",""))+1-COUNTBLANK(V18)-X18 -> 7.5 | X18: 1.5
A19: 12 | B19: =사원명부!B19 -> 주임연구원 | C19: =사원명부!D19 -> 정승후 | D19: =IF(B19=0,"-",사원명부!E19) -> 2018-07-02 | E19: =IF(B19=0,"-",D19+1) -> 43284 | F19: 17 | H19: =IFERROR(F19+G19,"") -> 17 | I19: =W19 -> 13.5 | J19: =IFERROR(F19+G19-I19,"") -> 3.5 | K19: 3일(오후반차), 8일(오후반차), 9일(오후반차), 15일(오후반차), 17일(오전반차), 24일, 31일(오후반차) | L19: 14일(오전반차), 19일(오후반차) | M19: 14(오후반차), 25(오전반차) | N19: 8일, 18일(오후반차), 22일(오후반차), 23일(오전반차) | O19: 2일, 9일(오후반차), 19일(오후반차) | P19: 13일(오후반차), 27일(오후반차) | Q19: 15(오후반차), 16(오전반차), 18일(오후반차) | R19: 18일(오후반차) | W19: =LEN(K19)-LEN(SUBSTITUTE(K19,",",""))+1-COUNTBLANK(K19)+LEN(L19)-LEN(SUBSTITUTE(L19,",",""))+1-COUNTBLANK(L19)+LEN(M19)-LEN(SUBSTITUTE(M19,",",""))+1-COUNTBLANK(M19)+LEN(N19)-LEN(SUBSTITUTE(N19,",",""))+1-COUNTBLANK(N19)+LEN(O19)-LEN(SUBSTITUTE(O19,",",""))+1-COUNTBLANK(O19)+LEN(P19)-LEN(SUBSTITUTE(P19,",",""))+1-COUNTBLANK(P19)+LEN(Q19)-LEN(SUBSTITUTE(Q19,",",""))+1-COUNTBLANK(Q19)+LEN(R19)-LEN(SUBSTITUTE(R19,",",""))+1-COUNTBLANK(R19)+LEN(S19)-LEN(SUBSTITUTE(S19,",",""))+1-COUNTBLANK(S19)+LEN(T19)-LEN(SUBSTITUTE(T19,",",""))+1-COUNTBLANK(T19)+LEN(U19)-LEN(SUBSTITUTE(U19,",",""))+1-COUNTBLANK(U19)+LEN(V19)-LEN(SUBSTITUTE(V19,",",""))+1-COUNTBLANK(V19)-X19 -> 13.5 | X19: 10.5
A20: 13 | B20: =사원명부!B20 -> 대리 | C20: =사원명부!D20 -> 나유성 | D20: =IF(B20=0,"-",사원명부!E20) -> 2018-09-27 | E20: =IF(B20=0,"-",D20+1) -> 43371 | F20: 17 | H20: =IFERROR(F20+G20,"") -> 17 | I20: =W20 -> 6.5 | J20: =IFERROR(F20+G20-I20,"") -> 10.5 | K20: 17일(오전반차), 17일(오후반차) | L20: 28 | M20: 4일,5일 | N20: 25일 | P20: 20일(오후반차) | R20: 1일(오전반차), 14일(오후반차) | W20: =LEN(K20)-LEN(SUBSTITUTE(K20,",",""))+1-COUNTBLANK(K20)+LEN(L20)-LEN(SUBSTITUTE(L20,",",""))+1-COUNTBLANK(L20)+LEN(M20)-LEN(SUBSTITUTE(M20,",",""))+1-COUNTBLANK(M20)+LEN(N20)-LEN(SUBSTITUTE(N20,",",""))+1-COUNTBLANK(N20)+LEN(O20)-LEN(SUBSTITUTE(O20,",",""))+1-COUNTBLANK(O20)+LEN(P20)-LEN(SUBSTITUTE(P20,",",""))+1-COUNTBLANK(P20)+LEN(Q20)-LEN(SUBSTITUTE(Q20,",",""))+1-COUNTBLANK(Q20)+LEN(R20)-LEN(SUBSTITUTE(R20,",",""))+1-COUNTBLANK(R20)+LEN(S20)-LEN(SUBSTITUTE(S20,",",""))+1-COUNTBLANK(S20)+LEN(T20)-LEN(SUBSTITUTE(T20,",",""))+1-COUNTBLANK(T20)+LEN(U20)-LEN(SUBSTITUTE(U20,",",""))+1-COUNTBLANK(U20)+LEN(V20)-LEN(SUBSTITUTE(V20,",",""))+1-COUNTBLANK(V20)-X20 -> 6.5 | X20: 2.5
A21: 14 | B21: =사원명부!B21 -> 주임연구원 | C21: =사원명부!D21 -> 정현웅 | D21: =IF(B21=0,"-",사원명부!E21) -> 2018-07-25 | E21: =IF(B21=0,"-",D21+1) -> 43307 | F21: 17 | H21: =IFERROR(F21+G21,"") -> 17 | I21: =W21 -> 2 | J21: =IFERROR(F21+G21-I21,"") -> 15 | K21: 3일,9일(오전반차) | W21: =LEN(K21)-LEN(SUBSTITUTE(K21,",",""))+1-COUNTBLANK(K21)+LEN(L21)-LEN(SUBSTITUTE(L21,",",""))+1-COUNTBLANK(L21)+LEN(M21)-LEN(SUBSTITUTE(M21,",",""))+1-COUNTBLANK(M21)+LEN(N21)-LEN(SUBSTITUTE(N21,",",""))+1-COUNTBLANK(N21)+LEN(O21)-LEN(SUBSTITUTE(O21,",",""))+1-COUNTBLANK(O21)+LEN(P21)-LEN(SUBSTITUTE(P21,",",""))+1-COUNTBLANK(P21)+LEN(Q21)-LEN(SUBSTITUTE(Q21,",",""))+1-COUNTBLANK(Q21)+LEN(R21)-LEN(SUBSTITUTE(R21,",",""))+1-COUNTBLANK(R21)+LEN(S21)-LEN(SUBSTITUTE(S21,",",""))+1-COUNTBLANK(S21)+LEN(T21)-LEN(SUBSTITUTE(T21,",",""))+1-COUNTBLANK(T21)+LEN(U21)-LEN(SUBSTITUTE(U21,",",""))+1-COUNTBLANK(U21)+LEN(V21)-LEN(SUBSTITUTE(V21,",",""))+1-COUNTBLANK(V21)-X21 -> 2
A22: 15 | B22: =사원명부!B22 -> 팀장 | C22: =사원명부!D22 -> 정희웅 | D22: =IF(B22=0,"-",사원명부!E22) -> 2018-09-27 | E22: =IF(B22=0,"-",D22+1) -> 43371 | F22: 17 | H22: =IFERROR(F22+G22,"") -> 17 | I22: =W22 -> 9 | J22: =IFERROR(F22+G22-I22,"") -> 8 | K22: 17일,20일 | L22: 6일(오전반차), 10일(오후반차) 18일 | M22: 13(오전반차) | N22: 9일(오후반차), 17일 | P22: 11일,26일,27일,30일 | W22: =LEN(K22)-LEN(SUBSTITUTE(K22,",",""))+1-COUNTBLANK(K22)+LEN(L22)-LEN(SUBSTITUTE(L22,",",""))+1-COUNTBLANK(L22)+LEN(M22)-LEN(SUBSTITUTE(M22,",",""))+1-COUNTBLANK(M22)+LEN(N22)-LEN(SUBSTITUTE(N22,",",""))+1-COUNTBLANK(N22)+LEN(O22)-LEN(SUBSTITUTE(O22,",",""))+1-COUNTBLANK(O22)+LEN(P22)-LEN(SUBSTITUTE(P22,",",""))+1-COUNTBLANK(P22)+LEN(Q22)-LEN(SUBSTITUTE(Q22,",",""))+1-COUNTBLANK(Q22)+LEN(R22)-LEN(SUBSTITUTE(R22,",",""))+1-COUNTBLANK(R22)+LEN(S22)-LEN(SUBSTITUTE(S22,",",""))+1-COUNTBLANK(S22)+LEN(T22)-LEN(SUBSTITUTE(T22,",",""))+1-COUNTBLANK(T22)+LEN(U22)-LEN(SUBSTITUTE(U22,",",""))+1-COUNTBLANK(U22)+LEN(V22)-LEN(SUBSTITUTE(V22,",",""))+1-COUNTBLANK(V22)-X22 -> 9 | X22: 2
A23: 16 | B23: =사원명부!B23 -> 대리 | C23: =사원명부!D23 -> 김희승 | D23: =IF(B23=0,"-",사원명부!E23) -> 2018-09-03 | E23: =IF(B23=0,"-",D23+1) -> 43347 | F23: 17 | H23: =IFERROR(F23+G23,"") -> 17 | I23: =W23 -> 13 | J23: =IFERROR(F23+G23-I23,"") -> 4 | K23: 3일(오후반차), 20일,23일 | L23: 14일(오후반차), 19일(오전반차) | M23: 06(오전반차), 25(오후반차) | N23: 14일(오후반차), 21일(오후반차), 22일(오후반차) | O23: 9일(오후반차), 16일(오후반차) | P23: 16일(오후반차), 26일,27일 | Q23: 31일,1일 | R23: 18일(오전반차), 11일, 8일(오후반차) | W23: =LEN(K23)-LEN(SUBSTITUTE(K23,",",""))+1-COUNTBLANK(K23)+LEN(L23)-LEN(SUBSTITUTE(L23,",",""))+1-COUNTBLANK(L23)+LEN(M23)-LEN(SUBSTITUTE(M23,",",""))+1-COUNTBLANK(M23)+LEN(N23)-LEN(SUBSTITUTE(N23,",",""))+1-COUNTBLANK(N23)+LEN(O23)-LEN(SUBSTITUTE(O23,",",""))+1-COUNTBLANK(O23)+LEN(P23)-LEN(SUBSTITUTE(P23,",",""))+1-COUNTBLANK(P23)+LEN(Q23)-LEN(SUBSTITUTE(Q23,",",""))+1-COUNTBLANK(Q23)+LEN(R23)-LEN(SUBSTITUTE(R23,",",""))+1-COUNTBLANK(R23)+LEN(S23)-LEN(SUBSTITUTE(S23,",",""))+1-COUNTBLANK(S23)+LEN(T23)-LEN(SUBSTITUTE(T23,",",""))+1-COUNTBLANK(T23)+LEN(U23)-LEN(SUBSTITUTE(U23,",",""))+1-COUNTBLANK(U23)+LEN(V23)-LEN(SUBSTITUTE(V23,",",""))+1-COUNTBLANK(V23)-X23 -> 13 | X23: 7
A24: 17 | B24: =사원명부!B24 -> 대리 | C24: =사원명부!D24 -> 곽병현 | D24: =IF(B24=0,"-",사원명부!E24) -> 2019-04-08 | E24: =IF(B24=0,"-",D24+1) -> 43564 | F24: 17 | G24: 0 | H24: =IFERROR(F24+G24,"") -> 17 | I24: =W24 -> 10.5 | J24: =IFERROR(F24+G24-I24,"") -> 6.5 | K24: 10일 | L24: 28일 | M24: 4일,5일 | O24: 15일(오후반차), 16일 | P24: 30일(오후반차) | Q24: 8일,9일,10일,11일 | R24: 13일(오후반차) | W24: =LEN(K24)-LEN(SUBSTITUTE(K24,",",""))+1-COUNTBLANK(K24)+LEN(L24)-LEN(SUBSTITUTE(L24,",",""))+1-COUNTBLANK(L24)+LEN(M24)-LEN(SUBSTITUTE(M24,",",""))+1-COUNTBLANK(M24)+LEN(N24)-LEN(SUBSTITUTE(N24,",",""))+1-COUNTBLANK(N24)+LEN(O24)-LEN(SUBSTITUTE(O24,",",""))+1-COUNTBLANK(O24)+LEN(P24)-LEN(SUBSTITUTE(P24,",",""))+1-COUNTBLANK(P24)+LEN(Q24)-LEN(SUBSTITUTE(Q24,",",""))+1-COUNTBLANK(Q24)+LEN(R24)-LEN(SUBSTITUTE(R24,",",""))+1-COUNTBLANK(R24)+LEN(S24)-LEN(SUBSTITUTE(S24,",",""))+1-COUNTBLANK(S24)+LEN(T24)-LEN(SUBSTITUTE(T24,",",""))+1-COUNTBLANK(T24)+LEN(U24)-LEN(SUBSTITUTE(U24,",",""))+1-COUNTBLANK(U24)+LEN(V24)-LEN(SUBSTITUTE(V24,",",""))+1-COUNTBLANK(V24)-X24 -> 10.5 | X24: 1.5
A25: 18 | B25: =사원명부!B25 -> 대리 | C25: =사원명부!D25 -> 윤은호 | D25: =IF(B25=0,"-",사원명부!E25) -> 2019-07-01 | E25: =IF(B25=0,"-",D25+1) -> 43648 | F25: 17 | G25: 1 | H25: =IFERROR(F25+G25,"") -> 18 | I25: =W25 -> 17.5 | J25: =IFERROR(F25+G25-I25,"") -> 0.5 | K25: 10일, 17일(오후반차) | L25: 7일, 14일(오후반차) | M25: 17,18, 28(오후반차) | N25: 11일, 22(오후반차) | O25: 22일 | P25: 10일(오후반차), 23일(오후반차), 27일 | Q25: 14일, 15일(오후반차), 18일,21일, 22일,23일,24일,25일 | W25: =LEN(K25)-LEN(SUBSTITUTE(K25,",",""))+1-COUNTBLANK(K25)+LEN(L25)-LEN(SUBSTITUTE(L25,",",""))+1-COUNTBLANK(L25)+LEN(M25)-LEN(SUBSTITUTE(M25,",",""))+1-COUNTBLANK(M25)+LEN(N25)-LEN(SUBSTITUTE(N25,",",""))+1-COUNTBLANK(N25)+LEN(O25)-LEN(SUBSTITUTE(O25,",",""))+1-COUNTBLANK(O25)+LEN(P25)-LEN(SUBSTITUTE(P25,",",""))+1-COUNTBLANK(P25)+LEN(Q25)-LEN(SUBSTITUTE(Q25,",",""))+1-COUNTBLANK(Q25)+LEN(R25)-LEN(SUBSTITUTE(R25,",",""))+1-COUNTBLANK(R25)+LEN(S25)-LEN(SUBSTITUTE(S25,",",""))+1-COUNTBLANK(S25)+LEN(T25)-LEN(SUBSTITUTE(T25,",",""))+1-COUNTBLANK(T25)+LEN(U25)-LEN(SUBSTITUTE(U25,",",""))+1-COUNTBLANK(U25)+LEN(V25)-LEN(SUBSTITUTE(V25,",",""))+1-COUNTBLANK(V25)-X25 -> 17.5 | X25: 3.5
A26: 19 | B26: =사원명부!B26 -> 주임연구원 | C26: =사원명부!D26 -> 김윤회 | D26: =IF(B26=0,"-",사원명부!E26) -> 2019-11-02 | E26: =IF(B26=0,"-",D26+1) -> 43772 | F26: 17 | G26: 1 | H26: =IFERROR(F26+G26,"") -> 18 | I26: =W26 -> 14.5 | J26: =IFERROR(F26+G26-I26,"") -> 3.5 | K26: 8일(오후반차), 9일 | L26: 14일 | M26: 7, 20(오후반차), 24 | N26: 1일(오후반차), 7일,8일, 9일,10일,11일,21일 | O26: 12일(오전반차), 26일(오전반차) | P26: 26일(오후반차) | R26: 1일(오후반차), 18일(오전반차) | W26: =LEN(K26)-LEN(SUBSTITUTE(K26,",",""))+1-COUNTBLANK(K26)+LEN(L26)-LEN(SUBSTITUTE(L26,",",""))+1-COUNTBLANK(L26)+LEN(M26)-LEN(SUBSTITUTE(M26,",",""))+1-COUNTBLANK(M26)+LEN(N26)-LEN(SUBSTITUTE(N26,",",""))+1-COUNTBLANK(N26)+LEN(O26)-LEN(SUBSTITUTE(O26,",",""))+1-COUNTBLANK(O26)+LEN(P26)-LEN(SUBSTITUTE(P26,",",""))+1-COUNTBLANK(P26)+LEN(Q26)-LEN(SUBSTITUTE(Q26,",",""))+1-COUNTBLANK(Q26)+LEN(R26)-LEN(SUBSTITUTE(R26,",",""))+1-COUNTBLANK(R26)+LEN(S26)-LEN(SUBSTITUTE(S26,",",""))+1-COUNTBLANK(S26)+LEN(T26)-LEN(SUBSTITUTE(T26,",",""))+1-COUNTBLANK(T26)+LEN(U26)-LEN(SUBSTITUTE(U26,",",""))+1-COUNTBLANK(U26)+LEN(V26)-LEN(SUBSTITUTE(V26,",",""))+1-COUNTBLANK(V26)-X26 -> 14.5 | X26: 3.5
A27: 20 | B27: =사원명부!B27 -> 반장 | C27: =사원명부!D27 -> 석진태 | D27: =IF(B27=0,"-",사원명부!E27) -> 2022-03-21 | E27: =IF(B27=0,"-",D27+1) -> 44642 | F27: 15 | H27: =IFERROR(F27+G27,"") -> 15 | I27: =W27 -> 8 | J27: =IFERROR(F27+G27-I27,"") -> 7 | K27: 3일,10일,14일 | L27: 3일 | M27: 12(오후반차) | O27: 19일(오후반차) | P27: 23일 | Q27: 02일 | R27: 5일 | W27: =LEN(K27)-LEN(SUBSTITUTE(K27,",",""))+1-COUNTBLANK(K27)+LEN(L27)-LEN(SUBSTITUTE(L27,",",""))+1-COUNTBLANK(L27)+LEN(M27)-LEN(SUBSTITUTE(M27,",",""))+1-COUNTBLANK(M27)+LEN(N27)-LEN(SUBSTITUTE(N27,",",""))+1-COUNTBLANK(N27)+LEN(O27)-LEN(SUBSTITUTE(O27,",",""))+1-COUNTBLANK(O27)+LEN(P27)-LEN(SUBSTITUTE(P27,",",""))+1-COUNTBLANK(P27)+LEN(Q27)-LEN(SUBSTITUTE(Q27,",",""))+1-COUNTBLANK(Q27)+LEN(R27)-LEN(SUBSTITUTE(R27,",",""))+1-COUNTBLANK(R27)+LEN(S27)-LEN(SUBSTITUTE(S27,",",""))+1-COUNTBLANK(S27)+LEN(T27)-LEN(SUBSTITUTE(T27,",",""))+1-COUNTBLANK(T27)+LEN(U27)-LEN(SUBSTITUTE(U27,",",""))+1-COUNTBLANK(U27)+LEN(V27)-LEN(SUBSTITUTE(V27,",",""))+1-COUNTBLANK(V27)-X27 -> 8 | X27: 1
A28: 21 | B28: =사원명부!B28 -> 사원 | C28: =사원명부!D28 -> 여도근 | D28: =IF(B28=0,"-",사원명부!E28) -> 2022-04-01 | E28: =IF(B28=0,"-",D28+1) -> 44653 | F28: 15 | H28: =IFERROR(F28+G28,"") -> 15 | I28: =W28 -> 7 | J28: =IFERROR(F28+G28-I28,"") -> 8 | K28: 6일(오후반차), 9일(오전반차), 24일(오후반차) | L28: 12일(오전반차) | M28: 24(오후반차) | N28: 1일(오전) | O28: 16일 | P28: 25일(오전반차), 30일 | Q28: 9일(오후반차), 28일 | W28: =LEN(K28)-LEN(SUBSTITUTE(K28,",",""))+1-COUNTBLANK(K28)+LEN(L28)-LEN(SUBSTITUTE(L28,",",""))+1-COUNTBLANK(L28)+LEN(M28)-LEN(SUBSTITUTE(M28,",",""))+1-COUNTBLANK(M28)+LEN(N28)-LEN(SUBSTITUTE(N28,",",""))+1-COUNTBLANK(N28)+LEN(O28)-LEN(SUBSTITUTE(O28,",",""))+1-COUNTBLANK(O28)+LEN(P28)-LEN(SUBSTITUTE(P28,",",""))+1-COUNTBLANK(P28)+LEN(Q28)-LEN(SUBSTITUTE(Q28,",",""))+1-COUNTBLANK(Q28)+LEN(R28)-LEN(SUBSTITUTE(R28,",",""))+1-COUNTBLANK(R28)+LEN(S28)-LEN(SUBSTITUTE(S28,",",""))+1-COUNTBLANK(S28)+LEN(T28)-LEN(SUBSTITUTE(T28,",",""))+1-COUNTBLANK(T28)+LEN(U28)-LEN(SUBSTITUTE(U28,",",""))+1-COUNTBLANK(U28)+LEN(V28)-LEN(SUBSTITUTE(V28,",",""))+1-COUNTBLANK(V28)-X28 -> 7 | X28: 4
A29: 22 | B29: =사원명부!B29 -> 사원 | C29: =사원명부!D29 -> 강영은 | D29: =IF(B29=0,"-",사원명부!E29) -> 2022-08-03 | E29: =IF(B29=0,"-",D29+1) -> 44777 | F29: 15 | H29: =IFERROR(F29+G29,"") -> 15 | I29: =W29 -> 5 | J29: =IFERROR(F29+G29-I29,"") -> 10 | K29: 9일(오후반차), 15일(오후반차) | L29: 14일(오후반차) | M29: 17, 25(오전반차) 25(오후반차) | P29: 18일(오전반차), 18일(오후반차) | Q29: 8일(오전반차) | R29: 18일 | W29: =LEN(K29)-LEN(SUBSTITUTE(K29,",",""))+1-COUNTBLANK(K29)+LEN(L29)-LEN(SUBSTITUTE(L29,",",""))+1-COUNTBLANK(L29)+LEN(M29)-LEN(SUBSTITUTE(M29,",",""))+1-COUNTBLANK(M29)+LEN(N29)-LEN(SUBSTITUTE(N29,",",""))+1-COUNTBLANK(N29)+LEN(O29)-LEN(SUBSTITUTE(O29,",",""))+1-COUNTBLANK(O29)+LEN(P29)-LEN(SUBSTITUTE(P29,",",""))+1-COUNTBLANK(P29)+LEN(Q29)-LEN(SUBSTITUTE(Q29,",",""))+1-COUNTBLANK(Q29)+LEN(R29)-LEN(SUBSTITUTE(R29,",",""))+1-COUNTBLANK(R29)+LEN(S29)-LEN(SUBSTITUTE(S29,",",""))+1-COUNTBLANK(S29)+LEN(T29)-LEN(SUBSTITUTE(T29,",",""))+1-COUNTBLANK(T29)+LEN(U29)-LEN(SUBSTITUTE(U29,",",""))+1-COUNTBLANK(U29)+LEN(V29)-LEN(SUBSTITUTE(V29,",",""))+1-COUNTBLANK(V29)-X29 -> 5 | X29: 4
A30: 23 | B30: =사원명부!B30 -> 사원 | C30: =사원명부!D30 -> 이한빈 | D30: =IF(B30=0,"-",사원명부!E30) -> 2023-01-01 | E30: =IF(B30=0,"-",D30+1) -> 44928 | F30: 15 | H30: =IFERROR(F30+G30,"") -> 15 | I30: =W30 -> 8.5 | J30: =IFERROR(F30+G30-I30,"") -> 6.5 | K30: 31일 | L30: 17일(오후반차), 18일 | M30: 21(오후반차) | N30: 4일 | P30: 27일,30일 | Q30: 28일,29일 | R30: 8일(오후반차) | W30: =LEN(K30)-LEN(SUBSTITUTE(K30,",",""))+1-COUNTBLANK(K30)+LEN(L30)-LEN(SUBSTITUTE(L30,",",""))+1-COUNTBLANK(L30)+LEN(M30)-LEN(SUBSTITUTE(M30,",",""))+1-COUNTBLANK(M30)+LEN(N30)-LEN(SUBSTITUTE(N30,",",""))+1-COUNTBLANK(N30)+LEN(O30)-LEN(SUBSTITUTE(O30,",",""))+1-COUNTBLANK(O30)+LEN(P30)-LEN(SUBSTITUTE(P30,",",""))+1-COUNTBLANK(P30)+LEN(Q30)-LEN(SUBSTITUTE(Q30,",",""))+1-COUNTBLANK(Q30)+LEN(R30)-LEN(SUBSTITUTE(R30,",",""))+1-COUNTBLANK(R30)+LEN(S30)-LEN(SUBSTITUTE(S30,",",""))+1-COUNTBLANK(S30)+LEN(T30)-LEN(SUBSTITUTE(T30,",",""))+1-COUNTBLANK(T30)+LEN(U30)-LEN(SUBSTITUTE(U30,",",""))+1-COUNTBLANK(U30)+LEN(V30)-LEN(SUBSTITUTE(V30,",",""))+1-COUNTBLANK(V30)-X30 -> 8.5 | X30: 1.5
A31: 24 | B31: =사원명부!B31 -> 사원 | C31: =사원명부!D31 -> 백현덕 | D31: =IF(B31=0,"-",사원명부!E31) -> 2023-03-06 | E31: =IF(B31=0,"-",D31+1) -> 44992 | F31: 15 | H31: =IFERROR(F31+G31,"") -> 15 | I31: =W31 -> 5.5 | J31: =IFERROR(F31+G31-I31,"") -> 9.5 | K31: 9일(오후반차) | L31: 28 | M31: 4,5 | P31: 24일(오후반차), 30일(오전반차) | R31: 4일 | W31: =LEN(K31)-LEN(SUBSTITUTE(K31,",",""))+1-COUNTBLANK(K31)+LEN(L31)-LEN(SUBSTITUTE(L31,",",""))+1-COUNTBLANK(L31)+LEN(M31)-LEN(SUBSTITUTE(M31,",",""))+1-COUNTBLANK(M31)+LEN(N31)-LEN(SUBSTITUTE(N31,",",""))+1-COUNTBLANK(N31)+LEN(O31)-LEN(SUBSTITUTE(O31,",",""))+1-COUNTBLANK(O31)+LEN(P31)-LEN(SUBSTITUTE(P31,",",""))+1-COUNTBLANK(P31)+LEN(Q31)-LEN(SUBSTITUTE(Q31,",",""))+1-COUNTBLANK(Q31)+LEN(R31)-LEN(SUBSTITUTE(R31,",",""))+1-COUNTBLANK(R31)+LEN(S31)-LEN(SUBSTITUTE(S31,",",""))+1-COUNTBLANK(S31)+LEN(T31)-LEN(SUBSTITUTE(T31,",",""))+1-COUNTBLANK(T31)+LEN(U31)-LEN(SUBSTITUTE(U31,",",""))+1-COUNTBLANK(U31)+LEN(V31)-LEN(SUBSTITUTE(V31,",",""))+1-COUNTBLANK(V31)-X31 -> 5.5 | X31: 1.5
A32: 25 | B32: =사원명부!B32 -> 사원 | C32: =사원명부!D32 -> 이종근 | D32: =IF(B32=0,"-",사원명부!E32) -> 45586 | E32: =IF(B32=0,"-",D32+1) -> 45587 | F32: 15 | H32: =IFERROR(F32+G32,"") -> 15 | I32: =W32 -> 6 | J32: =IFERROR(F32+G32-I32,"") -> 9 | N32: 4일 | P32: 2일,27일 | Q32: 21일,28일 | R32: 18일 | W32: =LEN(K32)-LEN(SUBSTITUTE(K32,",",""))+1-COUNTBLANK(K32)+LEN(L32)-LEN(SUBSTITUTE(L32,",",""))+1-COUNTBLANK(L32)+LEN(M32)-LEN(SUBSTITUTE(M32,",",""))+1-COUNTBLANK(M32)+LEN(N32)-LEN(SUBSTITUTE(N32,",",""))+1-COUNTBLANK(N32)+LEN(O32)-LEN(SUBSTITUTE(O32,",",""))+1-COUNTBLANK(O32)+LEN(P32)-LEN(SUBSTITUTE(P32,",",""))+1-COUNTBLANK(P32)+LEN(Q32)-LEN(SUBSTITUTE(Q32,",",""))+1-COUNTBLANK(Q32)+LEN(R32)-LEN(SUBSTITUTE(R32,",",""))+1-COUNTBLANK(R32)+LEN(S32)-LEN(SUBSTITUTE(S32,",",""))+1-COUNTBLANK(S32)+LEN(T32)-LEN(SUBSTITUTE(T32,",",""))+1-COUNTBLANK(T32)+LEN(U32)-LEN(SUBSTITUTE(U32,",",""))+1-COUNTBLANK(U32)+LEN(V32)-LEN(SUBSTITUTE(V32,",",""))+1-COUNTBLANK(V32)-X32 -> 6
A33: 26 | B33: =사원명부!B33 -> 사원 | C33: =사원명부!D33 -> 이채령 | D33: =IF(B33=0,"-",사원명부!E33) -> 45663 | E33: =IF(B33=0,"-",D33+1) -> 45664 | F33: 11 | H33: =IFERROR(F33+G33,"") -> 11 | I33: =W33 -> 2 | J33: =IFERROR(F33+G33-I33,"") -> 9 | K33: 10일(오후반차) | L33: 7일(오후반차) | M33: 14(오후반차) | R33: 7일(오후반차) | W33: =LEN(K33)-LEN(SUBSTITUTE(K33,",",""))+1-COUNTBLANK(K33)+LEN(L33)-LEN(SUBSTITUTE(L33,",",""))+1-COUNTBLANK(L33)+LEN(M33)-LEN(SUBSTITUTE(M33,",",""))+1-COUNTBLANK(M33)+LEN(N33)-LEN(SUBSTITUTE(N33,",",""))+1-COUNTBLANK(N33)+LEN(O33)-LEN(SUBSTITUTE(O33,",",""))+1-COUNTBLANK(O33)+LEN(P34)-LEN(SUBSTITUTE(P34,",",""))+1-COUNTBLANK(P34)+LEN(Q33)-LEN(SUBSTITUTE(Q33,",",""))+1-COUNTBLANK(Q33)+LEN(R33)-LEN(SUBSTITUTE(R33,",",""))+1-COUNTBLANK(R33)+LEN(S33)-LEN(SUBSTITUTE(S33,",",""))+1-COUNTBLANK(S33)+LEN(T33)-LEN(SUBSTITUTE(T33,",",""))+1-COUNTBLANK(T33)+LEN(U33)-LEN(SUBSTITUTE(U33,",",""))+1-COUNTBLANK(U33)+LEN(V33)-LEN(SUBSTITUTE(V33,",",""))+1-COUNTBLANK(V33)-X33 -> 2 | X33: 2
A34: 27 | B34: =사원명부!B34 -> 0 | C34: =사원명부!D34 -> 0 | D34: =IF(B34=0,"-",사원명부!E34) -> - | E34: =IF(B34=0,"-",D34+1) -> - | H34: =IFERROR(F34+G34,"") -> 0 | I34: =W34 -> #REF! | J34: =IFERROR(F34+G34-I34,"") | W34: =LEN(K34)-LEN(SUBSTITUTE(K34,",",""))+1-COUNTBLANK(K34)+LEN(L34)-LEN(SUBSTITUTE(L34,",",""))+1-COUNTBLANK(L34)+LEN(M34)-LEN(SUBSTITUTE(M34,",",""))+1-COUNTBLANK(M34)+LEN(N34)-LEN(SUBSTITUTE(N34,",",""))+1-COUNTBLANK(N34)+LEN(O34)-LEN(SUBSTITUTE(O34,",",""))+1-COUNTBLANK(O34)+LEN(#REF!)-LEN(SUBSTITUTE(#REF!,",",""))+1-COUNTBLANK(#REF!)+LEN(Q34)-LEN(SUBSTITUTE(Q34,",",""))+1-COUNTBLANK(Q34)+LEN(R34)-LEN(SUBSTITUTE(R34,",",""))+1-COUNTBLANK(R34)+LEN(S34)-LEN(SUBSTITUTE(S34,",",""))+1-COUNTBLANK(S34)+LEN(T34)-LEN(SUBSTITUTE(T34,",",""))+1-COUNTBLANK(T34)+LEN(U34)-LEN(SUBSTITUTE(U34,",",""))+1-COUNTBLANK(U34)+LEN(V34)-LEN(SUBSTITUTE(V34,",",""))+1-COUNTBLANK(V34)-X34 -> #REF!
A35: 28 | B35: =사원명부!B35 -> 사원 | C35: =사원명부!D35 -> 최창진 | D35: =IF(B35=0,"-",사원명부!E35) -> 45694 | E35: =IF(B35=0,"-",D35+1) -> 45695 | F35: 10 | H35: =IFERROR(F35+G35,"") -> 10 | I35: =W35 -> 3 | J35: =IFERROR(F35+G35-I35,"") -> 7 | M35: 28(오후반차) | N35: 4일(오후반차) | P35: 4일, 12일(오후반차) | R35: 14일(오후반차) | W35: =LEN(K35)-LEN(SUBSTITUTE(K35,",",""))+1-COUNTBLANK(K35)+LEN(L35)-LEN(SUBSTITUTE(L35,",",""))+1-COUNTBLANK(L35)+LEN(M35)-LEN(SUBSTITUTE(M35,",",""))+1-COUNTBLANK(M35)+LEN(N35)-LEN(SUBSTITUTE(N35,",",""))+1-COUNTBLANK(N35)+LEN(O35)-LEN(SUBSTITUTE(O35,",",""))+1-COUNTBLANK(O35)+LEN(P35)-LEN(SUBSTITUTE(P35,",",""))+1-COUNTBLANK(P35)+LEN(Q35)-LEN(SUBSTITUTE(Q35,",",""))+1-COUNTBLANK(Q35)+LEN(R35)-LEN(SUBSTITUTE(R35,",",""))+1-COUNTBLANK(R35)+LEN(S35)-LEN(SUBSTITUTE(S35,",",""))+1-COUNTBLANK(S35)+LEN(T35)-LEN(SUBSTITUTE(T35,",",""))+1-COUNTBLANK(T35)+LEN(U35)-LEN(SUBSTITUTE(U35,",",""))+1-COUNTBLANK(U35)+LEN(V35)-LEN(SUBSTITUTE(V35,",",""))+1-COUNTBLANK(V35)-X35 -> 3 | X35: 2
A36: 29 | B36: =사원명부!B36 -> 0 | C36: =사원명부!D36 -> 0 | D36: =IF(B36=0,"-",사원명부!E36) -> - | E36: =IF(B36=0,"-",D36+1) -> - | H36: =IFERROR(F36+G36,"") -> 0 | I36: =W36 -> 0 | J36: =IFERROR(F36+G36-I36,"") -> 0 | W36: =LEN(K36)-LEN(SUBSTITUTE(K36,",",""))+1-COUNTBLANK(K36)+LEN(L36)-LEN(SUBSTITUTE(L36,",",""))+1-COUNTBLANK(L36)+LEN(M36)-LEN(SUBSTITUTE(M36,",",""))+1-COUNTBLANK(M36)+LEN(N36)-LEN(SUBSTITUTE(N36,",",""))+1-COUNTBLANK(N36)+LEN(O36)-LEN(SUBSTITUTE(O36,",",""))+1-COUNTBLANK(O36)+LEN(P36)-LEN(SUBSTITUTE(P36,",",""))+1-COUNTBLANK(P36)+LEN(Q36)-LEN(SUBSTITUTE(Q36,",",""))+1-COUNTBLANK(Q36)+LEN(R36)-LEN(SUBSTITUTE(R36,",",""))+1-COUNTBLANK(R36)+LEN(S36)-LEN(SUBSTITUTE(S36,",",""))+1-COUNTBLANK(S36)+LEN(T36)-LEN(SUBSTITUTE(T36,",",""))+1-COUNTBLANK(T36)+LEN(U36)-LEN(SUBSTITUTE(U36,",",""))+1-COUNTBLANK(U36)+LEN(V36)-LEN(SUBSTITUTE(V36,",",""))+1-COUNTBLANK(V36)-X36 -> 0
A37: 30 | B37: =사원명부!B37 -> 0 | C37: =사원명부!D37 -> 0 | D37: =IF(B37=0,"-",사원명부!E37) -> - | E37: =IF(B37=0,"-",D37+1) -> - | H37: =IFERROR(F37+G37,"") -> 0 | I37: =W37 -> 0 | J37: =IFERROR(F37+G37-I37,"") -> 0 | W37: =LEN(K37)-LEN(SUBSTITUTE(K37,",",""))+1-COUNTBLANK(K37)+LEN(L37)-LEN(SUBSTITUTE(L37,",",""))+1-COUNTBLANK(L37)+LEN(M37)-LEN(SUBSTITUTE(M37,",",""))+1-COUNTBLANK(M37)+LEN(N37)-LEN(SUBSTITUTE(N37,",",""))+1-COUNTBLANK(N37)+LEN(O37)-LEN(SUBSTITUTE(O37,",",""))+1-COUNTBLANK(O37)+LEN(P37)-LEN(SUBSTITUTE(P37,",",""))+1-COUNTBLANK(P37)+LEN(Q37)-LEN(SUBSTITUTE(Q37,",",""))+1-COUNTBLANK(Q37)+LEN(R37)-LEN(SUBSTITUTE(R37,",",""))+1-COUNTBLANK(R37)+LEN(S37)-LEN(SUBSTITUTE(S37,",",""))+1-COUNTBLANK(S37)+LEN(T37)-LEN(SUBSTITUTE(T37,",",""))+1-COUNTBLANK(T37)+LEN(U37)-LEN(SUBSTITUTE(U37,",",""))+1-COUNTBLANK(U37)+LEN(V37)-LEN(SUBSTITUTE(V37,",",""))+1-COUNTBLANK(V37)-X37 -> 0
A38: 31 | B38: =사원명부!B38 -> 0 | C38: =사원명부!D38 -> 0 | D38: =IF(B38=0,"-",사원명부!E38) -> - | E38: =IF(B38=0,"-",D38+1) -> - | H38: =IFERROR(F38+G38,"") -> 0 | I38: =W38 -> 0 | J38: =IFERROR(F38+G38-I38,"") -> 0 | W38: =LEN(K38)-LEN(SUBSTITUTE(K38,",",""))+1-COUNTBLANK(K38)+LEN(L38)-LEN(SUBSTITUTE(L38,",",""))+1-COUNTBLANK(L38)+LEN(M38)-LEN(SUBSTITUTE(M38,",",""))+1-COUNTBLANK(M38)+LEN(N38)-LEN(SUBSTITUTE(N38,",",""))+1-COUNTBLANK(N38)+LEN(O38)-LEN(SUBSTITUTE(O38,",",""))+1-COUNTBLANK(O38)+LEN(P38)-LEN(SUBSTITUTE(P38,",",""))+1-COUNTBLANK(P38)+LEN(Q38)-LEN(SUBSTITUTE(Q38,",",""))+1-COUNTBLANK(Q38)+LEN(R38)-LEN(SUBSTITUTE(R38,",",""))+1-COUNTBLANK(R38)+LEN(S38)-LEN(SUBSTITUTE(S38,",",""))+1-COUNTBLANK(S38)+LEN(T38)-LEN(SUBSTITUTE(T38,",",""))+1-COUNTBLANK(T38)+LEN(U38)-LEN(SUBSTITUTE(U38,",",""))+1-COUNTBLANK(U38)+LEN(V38)-LEN(SUBSTITUTE(V38,",",""))+1-COUNTBLANK(V38)-X38 -> 0
A39: 32 | B39: =사원명부!B39 -> 0 | C39: =사원명부!D39 -> 0 | D39: =IF(B39=0,"-",사원명부!E39) -> - | E39: =IF(B39=0,"-",D39+1) -> - | H39: =IFERROR(F39+G39,"") -> 0 | I39: =W39 -> 0 | J39: =IFERROR(F39+G39-I39,"") -> 0 | W39: =LEN(K39)-LEN(SUBSTITUTE(K39,",",""))+1-COUNTBLANK(K39)+LEN(L39)-LEN(SUBSTITUTE(L39,",",""))+1-COUNTBLANK(L39)+LEN(M39)-LEN(SUBSTITUTE(M39,",",""))+1-COUNTBLANK(M39)+LEN(N39)-LEN(SUBSTITUTE(N39,",",""))+1-COUNTBLANK(N39)+LEN(O39)-LEN(SUBSTITUTE(O39,",",""))+1-COUNTBLANK(O39)+LEN(P39)-LEN(SUBSTITUTE(P39,",",""))+1-COUNTBLANK(P39)+LEN(Q39)-LEN(SUBSTITUTE(Q39,",",""))+1-COUNTBLANK(Q39)+LEN(R39)-LEN(SUBSTITUTE(R39,",",""))+1-COUNTBLANK(R39)+LEN(S39)-LEN(SUBSTITUTE(S39,",",""))+1-COUNTBLANK(S39)+LEN(T39)-LEN(SUBSTITUTE(T39,",",""))+1-COUNTBLANK(T39)+LEN(U39)-LEN(SUBSTITUTE(U39,",",""))+1-COUNTBLANK(U39)+LEN(V39)-LEN(SUBSTITUTE(V39,",",""))+1-COUNTBLANK(V39)-X39 -> 0
A40: 33 | B40: =사원명부!B40 -> 0 | C40: =사원명부!D40 -> 0 | D40: =IF(B40=0,"-",사원명부!E40) -> - | E40: =IF(B40=0,"-",D40+1) -> - | H40: =IFERROR(F40+G40,"") -> 0 | I40: =W40 -> 0 | J40: =IFERROR(F40+G40-I40,"") -> 0 | W40: =LEN(K40)-LEN(SUBSTITUTE(K40,",",""))+1-COUNTBLANK(K40)+LEN(L40)-LEN(SUBSTITUTE(L40,",",""))+1-COUNTBLANK(L40)+LEN(M40)-LEN(SUBSTITUTE(M40,",",""))+1-COUNTBLANK(M40)+LEN(N40)-LEN(SUBSTITUTE(N40,",",""))+1-COUNTBLANK(N40)+LEN(O40)-LEN(SUBSTITUTE(O40,",",""))+1-COUNTBLANK(O40)+LEN(P40)-LEN(SUBSTITUTE(P40,",",""))+1-COUNTBLANK(P40)+LEN(Q40)-LEN(SUBSTITUTE(Q40,",",""))+1-COUNTBLANK(Q40)+LEN(R40)-LEN(SUBSTITUTE(R40,",",""))+1-COUNTBLANK(R40)+LEN(S40)-LEN(SUBSTITUTE(S40,",",""))+1-COUNTBLANK(S40)+LEN(T40)-LEN(SUBSTITUTE(T40,",",""))+1-COUNTBLANK(T40)+LEN(U40)-LEN(SUBSTITUTE(U40,",",""))+1-COUNTBLANK(U40)+LEN(V40)-LEN(SUBSTITUTE(V40,",",""))+1-COUNTBLANK(V40)-X40 -> 0
A41: 34 | B41: =사원명부!B41 -> 0 | C41: =사원명부!D41 -> 0 | D41: =IF(B41=0,"-",사원명부!E41) -> - | E41: =IF(B41=0,"-",D41+1) -> - | H41: =IFERROR(F41+G41,"") -> 0 | I41: =W41 -> 0 | J41: =IFERROR(F41+G41-I41,"") -> 0 | W41: =LEN(K41)-LEN(SUBSTITUTE(K41,",",""))+1-COUNTBLANK(K41)+LEN(L41)-LEN(SUBSTITUTE(L41,",",""))+1-COUNTBLANK(L41)+LEN(M41)-LEN(SUBSTITUTE(M41,",",""))+1-COUNTBLANK(M41)+LEN(N41)-LEN(SUBSTITUTE(N41,",",""))+1-COUNTBLANK(N41)+LEN(O41)-LEN(SUBSTITUTE(O41,",",""))+1-COUNTBLANK(O41)+LEN(P41)-LEN(SUBSTITUTE(P41,",",""))+1-COUNTBLANK(P41)+LEN(Q41)-LEN(SUBSTITUTE(Q41,",",""))+1-COUNTBLANK(Q41)+LEN(R41)-LEN(SUBSTITUTE(R41,",",""))+1-COUNTBLANK(R41)+LEN(S41)-LEN(SUBSTITUTE(S41,",",""))+1-COUNTBLANK(S41)+LEN(T41)-LEN(SUBSTITUTE(T41,",",""))+1-COUNTBLANK(T41)+LEN(U41)-LEN(SUBSTITUTE(U41,",",""))+1-COUNTBLANK(U41)+LEN(V41)-LEN(SUBSTITUTE(V41,",",""))+1-COUNTBLANK(V41)-X41 -> 0
A42: 35 | B42: =사원명부!B42 -> 0 | C42: =사원명부!D42 -> 0 | D42: =IF(B42=0,"-",사원명부!E42) -> - | E42: =IF(B42=0,"-",D42+1) -> - | H42: =IFERROR(F42+G42,"") -> 0 | I42: =W42 -> 0 | J42: =IFERROR(F42+G42-I42,"") -> 0 | W42: =LEN(K42)-LEN(SUBSTITUTE(K42,",",""))+1-COUNTBLANK(K42)+LEN(L42)-LEN(SUBSTITUTE(L42,",",""))+1-COUNTBLANK(L42)+LEN(M42)-LEN(SUBSTITUTE(M42,",",""))+1-COUNTBLANK(M42)+LEN(N42)-LEN(SUBSTITUTE(N42,",",""))+1-COUNTBLANK(N42)+LEN(O42)-LEN(SUBSTITUTE(O42,",",""))+1-COUNTBLANK(O42)+LEN(P42)-LEN(SUBSTITUTE(P42,",",""))+1-COUNTBLANK(P42)+LEN(Q42)-LEN(SUBSTITUTE(Q42,",",""))+1-COUNTBLANK(Q42)+LEN(R42)-LEN(SUBSTITUTE(R42,",",""))+1-COUNTBLANK(R42)+LEN(S42)-LEN(SUBSTITUTE(S42,",",""))+1-COUNTBLANK(S42)+LEN(T42)-LEN(SUBSTITUTE(T42,",",""))+1-COUNTBLANK(T42)+LEN(U42)-LEN(SUBSTITUTE(U42,",",""))+1-COUNTBLANK(U42)+LEN(V42)-LEN(SUBSTITUTE(V42,",",""))+1-COUNTBLANK(V42)-X42 -> 0
A43: 36 | B43: =사원명부!B43 -> 0 | C43: =사원명부!D43 -> 0 | D43: =IF(B43=0,"-",사원명부!E43) -> - | E43: =IF(B43=0,"-",D43+1) -> - | H43: =IFERROR(F43+G43,"") -> 0 | I43: =W43 -> 0 | J43: =IFERROR(F43+G43-I43,"") -> 0 | W43: =LEN(K43)-LEN(SUBSTITUTE(K43,",",""))+1-COUNTBLANK(K43)+LEN(L43)-LEN(SUBSTITUTE(L43,",",""))+1-COUNTBLANK(L43)+LEN(M43)-LEN(SUBSTITUTE(M43,",",""))+1-COUNTBLANK(M43)+LEN(N43)-LEN(SUBSTITUTE(N43,",",""))+1-COUNTBLANK(N43)+LEN(O43)-LEN(SUBSTITUTE(O43,",",""))+1-COUNTBLANK(O43)+LEN(P43)-LEN(SUBSTITUTE(P43,",",""))+1-COUNTBLANK(P43)+LEN(Q43)-LEN(SUBSTITUTE(Q43,",",""))+1-COUNTBLANK(Q43)+LEN(R43)-LEN(SUBSTITUTE(R43,",",""))+1-COUNTBLANK(R43)+LEN(S43)-LEN(SUBSTITUTE(S43,",",""))+1-COUNTBLANK(S43)+LEN(T43)-LEN(SUBSTITUTE(T43,",",""))+1-COUNTBLANK(T43)+LEN(U43)-LEN(SUBSTITUTE(U43,",",""))+1-COUNTBLANK(U43)+LEN(V43)-LEN(SUBSTITUTE(V43,",",""))+1-COUNTBLANK(V43)-X43 -> 0
A44: 37 | B44: =사원명부!B44 -> 0 | C44: =사원명부!D44 -> 0 | D44: =IF(B44=0,"-",사원명부!E44) -> - | E44: =IF(B44=0,"-",D44+1) -> - | H44: =IFERROR(F44+G44,"") -> 0 | I44: =W44 -> 0 | J44: =IFERROR(F44+G44-I44,"") -> 0 | W44: =LEN(K44)-LEN(SUBSTITUTE(K44,",",""))+1-COUNTBLANK(K44)+LEN(L44)-LEN(SUBSTITUTE(L44,",",""))+1-COUNTBLANK(L44)+LEN(M44)-LEN(SUBSTITUTE(M44,",",""))+1-COUNTBLANK(M44)+LEN(N44)-LEN(SUBSTITUTE(N44,",",""))+1-COUNTBLANK(N44)+LEN(O44)-LEN(SUBSTITUTE(O44,",",""))+1-COUNTBLANK(O44)+LEN(P44)-LEN(SUBSTITUTE(P44,",",""))+1-COUNTBLANK(P44)+LEN(Q44)-LEN(SUBSTITUTE(Q44,",",""))+1-COUNTBLANK(Q44)+LEN(R44)-LEN(SUBSTITUTE(R44,",",""))+1-COUNTBLANK(R44)+LEN(S44)-LEN(SUBSTITUTE(S44,",",""))+1-COUNTBLANK(S44)+LEN(T44)-LEN(SUBSTITUTE(T44,",",""))+1-COUNTBLANK(T44)+LEN(U44)-LEN(SUBSTITUTE(U44,",",""))+1-COUNTBLANK(U44)+LEN(V44)-LEN(SUBSTITUTE(V44,",",""))+1-COUNTBLANK(V44)-X44 -> 0
...

Sheet 휴가대장 출력용
O2: * 출력 전에 출력되는 페이지 확인바랍니다.
P4: 대표 결재란 | Q4: 담당자 결재란
I6: 연차휴가 관리대장
A7: =사원명부!J5&" "&사원명부!I6&" : "&사원명부!J6&" "&사원명부!J8 -> ㈜한슬 대표자 : 정영수 대구 달서구 성서공단북로 305
B11: 성 명 | C11: 입사일 | D11: 사용가능 연차 | E11: (-)사용연차 | F11: (=)남은연차 | G11: 월별 휴가 사용내역
G12: 01월 | H12: 02월 | I12: 03월 | J12: 04월 | K12: 05월 | L12: 06월 | M12: 07월 | N12: 08월 | O12: 09월 | P12: 10월 | Q12: 11월 | R12: 12월
A13: 1 | B13: ='휴가대장 관리용'!C8 -> 양승진 | C13: ='휴가대장 관리용'!D8 -> 1990-09-01 | D13: ='휴가대장 관리용'!H8 -> 25 | E13: ='휴가대장 관리용'!I8 -> 10.5 | F13: ='휴가대장 관리용'!J8 -> 14.5 | G13: ='휴가대장 관리용'!K8 -> 0 | H13: ='휴가대장 관리용'!L8 -> 0 | I13: ='휴가대장 관리용'!M8 -> 27일(오전반차) | J13: ='휴가대장 관리용'!N8 -> 2일, 15일(오후반차) | K13: ='휴가대장 관리용'!O8 -> 02일 | ... R13: ='휴가대장 관리용'!V8 -> 0
A14: 2 | B14: ='휴가대장 관리용'!C9 -> 최창열 | C14: ='휴가대장 관리용'!D9 -> 2000-10-01 | D14: ='휴가대장 관리용'!H9 -> 25 | E14: ='휴가대장 관리용'!I9 -> 10 | F14: ='휴가대장 관리용'!J9 -> 15 | G14: ='휴가대장 관리용'!K9 -> 0 | H14: ='휴가대장 관리용'!L9 -> 24일(오후반차) | I14: ='휴가대장 관리용'!M9 -> 28일(오후반차) | J14: ='휴가대장 관리용'!N9 -> 29일,30일 | K14: ='휴가대장 관리용'!O9 -> 28일 | ... R14: ='휴가대장 관리용'!V9 -> 0
A15: 3 | B15: ='휴가대장 관리용'!C10 -> 김은정 | C15: ='휴가대장 관리용'!D10 -> 2002-07-26 | D15: ='휴가대장 관리용'!H10 -> 25 | E15: ='휴가대장 관리용'!I10 -> 14 | F15: ='휴가대장 관리용'!J10 -> 11 | G15: ='휴가대장 관리용'!K10 -> 22일 | H15: ='휴가대장 관리용'!L10 -> 20일,27,28 | I15: ='휴가대장 관리용'!M10 -> 05(오후반차),12 | J15: ='휴가대장 관리용'!N10 -> 23일, 28일(오후반차) | K15: ='휴가대장 관리용'!O10 -> 0 | ... R15: ='휴가대장 관리용'!V10 -> 0
A16: 4 | B16: ='휴가대장 관리용'!C11 -> 이정화 | C16: ='휴가대장 관리용'!D11 -> 2003-01-02 | D16: ='휴가대장 관리용'!H11 -> 25 | E16: ='휴가대장 관리용'!I11 -> 15.5 | F16: ='휴가대장 관리용'!J11 -> 9.5 | G16: ='휴가대장 관리용'!K11 -> 17일(오후반차), 31일(오후반차) | H16: ='휴가대장 관리용'!L11 -> 7일(오후반차), 21일,28일 | I16: ='휴가대장 관리용'!M11 -> 14(오후반차) | J16: ='휴가대장 관리용'!N11 -> 2일,25일 | K16: ='휴가대장 관리용'!O11 -> 2일, 29일(오후반차) | ... R16: ='휴가대장 관리용'!V11 -> 0
A17: 5 | B17: ='휴가대장 관리용'!C12 -> 하치복 | C17: ='휴가대장 관리용'!D12 -> 2004-03-15 | D17: ='휴가대장 관리용'!H12 -> 25 | E17: ='휴가대장 관리용'!I12 -> 6.5 | F17: ='휴가대장 관리용'!J12 -> 18.5 | G17: ='휴가대장 관리용'!K12 -> 10일 | H17: ='휴가대장 관리용'!L12 -> 21일 | I17: ='휴가대장 관리용'!M12 -> 28 | J17: ='휴가대장 관리용'!N12 -> 18일 | K17: ='휴가대장 관리용'!O12 -> 0 | ... R17: ='휴가대장 관리용'!V12 -> 0
A18: 6 | B18: ='휴가대장 관리용'!C13 -> 권혁진 | C18: ='휴가대장 관리용'!D13 -> 2004-11-10 | D18: ='휴가대장 관리용'!H13 -> 25 | E18: ='휴가대장 관리용'!I13 -> 3 | F18: ='휴가대장 관리용'!J13 -> 22 | G18: ='휴가대장 관리용'!K13 -> 3일(오후반자), 20일,31일 | H18: ='휴가대장 관리용'!L13 -> 7일(오후반차) | I18: ='휴가대장 관리용'!M13 -> 0 | J18: ='휴가대장 관리용'!N13 -> 0 | K18: ='휴가대장 관리용'!O13 -> 0 | ... R18: ='휴가대장 관리용'!V13 -> 0
A19: 7 | B19: ='휴가대장 관리용'!C14 -> 김경태 | C19: ='휴가대장 관리용'!D14 -> 2013-04-26 | D19: ='휴가대장 관리용'!H14 -> 20 | E19: ='휴가대장 관리용'!I14 -> 11 | F19: ='휴가대장 관리용'!J14 -> 9 | G19: ='휴가대장 관리용'!K14 -> 10일(오후반차), 31일 | H19: ='휴가대장 관리용'!L14 -> 11일,12일,13일,19일 | I19: ='휴가대장 관리용'!M14 -> 4일 | J19: ='휴가대장 관리용'!N14 -> 7일, 23일(오후반차) | K19: ='휴가대장 관리용'!O14 -> 0 | ... R19: ='휴가대장 관리용'!V14 -> 0
A20: 8 | B20: ='휴가대장 관리용'!C15 -> 조근일 | C20: ='휴가대장 관리용'!D15 -> 2013-11-04 | D20: ='휴가대장 관리용'!H15 -> 20 | E20: ='휴가대장 관리용'!I15 -> 6.5 | F20: ='휴가대장 관리용'!J15 -> 13.5 | G20: ='휴가대장 관리용'!K15 -> 2일 | H20: ='휴가대장 관리용'!L15 -> 12일,13일,14일 | I20: ='휴가대장 관리용'!M15 -> 27(오전반차) | J20: ='휴가대장 관리용'!N15 -> 8일(오전반차) | K20: ='휴가대장 관리용'!O15 -> 28일(오후반차) | ... R20: ='휴가대장 관리용'!V15 -> 0
A21: 9 | B21: ='휴가대장 관리용'!C16 -> 이재형 | C21: ='휴가대장 관리용'!D16 -> 2015-03-16 | D21: ='휴가대장 관리용'!H16 -> 19 | E21: ='휴가대장 관리용'!I16 -> 9.5 | F21: ='휴가대장 관리용'!J16 -> 9.5 | G21: ='휴가대장 관리용'!K16 -> 9일(오전반차),14일, 20일(오후반차) | H21: ='휴가대장 관리용'!L16 -> 28일 | I21: ='휴가대장 관리용'!M16 -> 24(오후반차) | J21: ='휴가대장 관리용'!N16 -> 0 | K21: ='휴가대장 관리용'!O16 -> 2일 | ... R21: ='휴가대장 관리용'!V16 -> 0
A22: 10 | B22: ='휴가대장 관리용'!C17 -> 임소연 | C22: ='휴가대장 관리용'!D17 -> 2006-12-01 | D22: ='휴가대장 관리용'!H17 -> 23 | E22: ='휴가대장 관리용'!I17 -> 13.5 | F22: ='휴가대장 관리용'!J17 -> 9.5 | G22: ='휴가대장 관리용'!K17 -> 2일,8일(오전반차), 22일,31일 | H22: ='휴가대장 관리용'!L17 -> 28일 | I22: ='휴가대장 관리용'!M17 -> 4,25(오후반차) | J22: ='휴가대장 관리용'!N17 -> 17일,18일23일, 30일(오후반차) | K22: ='휴가대장 관리용'!O17 -> 27일(오전반차) | ... R22: ='휴가대장 관리용'!V17 -> 0
A23: 11 | B23: ='휴가대장 관리용'!C18 -> 김지혜 | C23: ='휴가대장 관리용'!D18 -> 2018-02-06 | D23: ='휴가대장 관리용'!H18 -> 17 | E23: ='휴가대장 관리용'!I18 -> 7.5 | F23: ='휴가대장 관리용'!J18 -> 9.5 | G23: ='휴가대장 관리용'!K18 -> 31일 | H23: ='휴가대장 관리용'!L18 -> 21일,28일 | I23: ='휴가대장 관리용'!M18 -> 0 | J23: ='휴가대장 관리용'!N18 -> 0 | K23: ='휴가대장 관리용'!O18 -> 0 | ... R23: ='휴가대장 관리용'!V18 -> 0
A24: 12 | B24: ='휴가대장 관리용'!C19 -> 정승후 | C24: ='휴가대장 관리용'!D19 -> 2018-07-02 | D24: ='휴가대장 관리용'!H19 -> 17 | E24: ='휴가대장 관리용'!I19 -> 13.5 | F24: ='휴가대장 관리용'!J19 -> 3.5 | G24: ='휴가대장 관리용'!K19 -> 3일(오후반차), 8일(오후반차), 9일(오후반차), 15일(오후반차), 17일(오전반차), 24일, 31일(오후반차) | H24: ='휴가대장 관리용'!L19 -> 14일(오전반차), 19일(오후반차) | I24: ='휴가대장 관리용'!M19 -> 14(오후반차), 25(오전반차) | J24: ='휴가대장 관리용'!N19 -> 8일, 18일(오후반차), 22일(오후반차), 23일(오전반차) | K24: ='휴가대장 관리용'!O19 -> 2일, 9일(오후반차), 19일(오후반차) | ... R24: ='휴가대장 관리용'!V19 -> 0
... A37: 25 | B37: ='휴가대장 관리용'!C32 -> 이종근 | C37: ='휴가대장 관리용'!D32 -> 45586 | D37: ='휴가대장 관리용'!H32 -> 15 | E37: ='휴가대장 관리용'!I32 -> 6 | F37: ='휴가대장 관리용'!J32 -> 9 | G37: ='휴가대장 관리용'!K32 -> 0 | H37: ='휴가대장 관리용'!L32 -> 0 | I37: ='휴가대장 관리용'!M32 -> 0 | J37: ='휴가대장 관리용'!N32 -> 4일 | K37: ='휴가대장 관리용'!O32 -> 0 | ... R37: ='휴가대장 관리용'!V32 -> 0
A38: 26 | B38: ='휴가대장 관리용'!C33 -> 이채령 | C38: ='휴가대장 관리용'!D33 -> 45663 | D38: ='휴가대장 관리용'!H33 -> 11 | E38: ='휴가대장 관리용'!I33 -> 2 | F38: ='휴가대장 관리용'!J33 -> 9 | G38: ='휴가대장 관리용'!K33 -> 10일(오후반차) | H38: ='휴가대장 관리용'!L33 -> 7일(오후반차) | I38: ='휴가대장 관리용'!M33 -> 14(오후반차) | J38: ='휴가대장 관리용'!N33 -> 0 | K38: ='휴가대장 관리용'!O33 -> 0 | L38: ='휴가대장 관리용'!P34 -> 0 | M38: ='휴가대장 관리용'!Q33 -> 0 | N38: ='휴가대장 관리용'!R33 -> 7일(오후반차) | O38: ='휴가대장 관리용'!S33 -> 0 | P38: ='휴가대장 관리용'!T33 -> 0 | Q38: ='휴가대장 관리용'!U33 -> 0 | R38: ='휴가대장 관리용'!V33 -> 0
A39: 27 | B39: ='휴가대장 관리용'!C34 -> 0 | C39: ='휴가대장 관리용'!D34 -> - | D39: ='휴가대장 관리용'!H34 -> 0 | E39: ='휴가대장 관리용'!I34 -> #REF! | F39: ='휴가대장 관리용'!J34 | G39: ='휴가대장 관리용'!K34 -> 0 | H39: ='휴가대장 관리용'!L34 -> 0 | I39: ='휴가대장 관리용'!M34 -> 0 | J39: ='휴가대장 관리용'!N34 -> 0 | K39: ='휴가대장 관리용'!O34 -> 0 | L39: ='휴가대장 관리용'!#REF! -> #REF! | M39: ='휴가대장 관리용'!Q34 -> 0 | N39: ='휴가대장 관리용'!R34 -> 0 | O39: ='휴가대장 관리용'!S34 -> 0 | P39: ='휴가대장 관리용'!T34 -> 0 | Q39: ='휴가대장 관리용'!U34 -> 0 | R39: ='휴가대장 관리용'!V34 -> 0
A40: 28 | B40: ='휴가대장 관리용'!C35 -> 최창진 | C40: ='휴가대장 관리용'!D35 -> 45694 | D40: ='휴가대장 관리용'!H35 -> 10 | E40: ='휴가대장 관리용'!I35 -> 3 | F40: ='휴가대장 관리용'!J35 -> 7 | G40: ='휴가대장 관리용'!K35 -> 0 | H40: ='휴가대장 관리용'!L35 -> 0 | I40: ='휴가대장 관리용'!M35 -> 28(오후반차) | J40: ='휴가대장 관리용'!N35 -> 4일(오후반차) | K40: ='휴가대장 관리용'!O35 -> 0 | ... R40: ='휴가대장 관리용'!V35 -> 0
A41: 29 | B41: ='휴가대장 관리용'!C36 -> 0 | C41: ='휴가대장 관리용'!D36 -> - | D41: ='휴가대장 관리용'!H36 -> 0 | E41: ='휴가대장 관리용'!I36 -> 0 | F41: ='휴가대장 관리용'!J36 -> 0 | G41: ='휴가대장 관리용'!K36 -> 0 | H41: ='휴가대장 관리용'!L36 -> 0 | I41: ='휴가대장 관리용'!M36 -> 0 | J41: ='휴가대장 관리용'!N36 -> 0 | K41: ='휴가대장 관리용'!O36 -> 0 | ... R41: ='휴가대장 관리용'!V36 -> 0
A42: 30 | B42: ='휴가대장 관리용'!C37 -> 0 | C42: ='휴가대장 관리용'!D37 -> - | D42: ='휴가대장 관리용'!H37 -> 0 | E42: ='휴가대장 관리용'!I37 -> 0 | F42: ='휴가대장 관리용'!J37 -> 0 | G42: ='휴가대장 관리용'!K37 -> 0 | H42: ='휴가대장 관리용'!L37 -> 0 | I42: ='휴가대장 관리용'!M37 -> 0 | J42: ='휴가대장 관리용'!N37 -> 0 | K42: ='휴가대장 관리용'!O37 -> 0 | ... R42: ='휴가대장 관리용'!V37 -> 0
A43: 31 | B43: ='휴가대장 관리용'!C38 -> 0 | C43: ='휴가대장 관리용'!D38 -> - | D43: ='휴가대장 관리용'!H38 -> 0 | E43: ='휴가대장 관리용'!I38 -> 0 | F43: ='휴가대장 관리용'!J38 -> 0 | G43: ='휴가대장 관리용'!K38 -> 0 | H43: ='휴가대장 관리용'!L38 -> 0 | I43: ='휴가대장 관리용'!M38 -> 0 | J43: ='휴가대장 관리용'!N38 -> 0 | K43: ='휴가대장 관리용'!O38 -> 0 | ... R43: ='휴가대장 관리용'!V38 -> 0
A44: 32 | B44: ='휴가대장 관리용'!C39 -> 0 | C44: ='휴가대장 관리용'!D39 -> - | D44: ='휴가대장 관리용'!H39 -> 0 | E44: ='휴가대장 관리용'!I39 -> 0 | F44: ='휴가대장 관리용'!J39 -> 0 | G44: ='휴가대장 관리용'!K39 -> 0 | H44: ='휴가대장 관리용'!L39 -> 0 | I44: ='휴가대장 관리용'!M39 -> 0 | J44: ='휴가대장 관리용'!N39 -> 0 | K44: ='휴가대장 관리용'!O39 -> 0 | ... R44: ='휴가대장 관리용'!V39 -> 0
A45: 33 | B45: ='휴가대장 관리용'!C40 -> 0 | C45: ='휴가대장 관리용'!D40 -> - | D45: ='휴가대장 관리용'!H40 -> 0 | E45: ='휴가대장 관리용'!I40 -> 0 | F45: ='휴가대장 관리용'!J40 -> 0 | G45: ='휴가대장 관리용'!K40 -> 0 | H45: ='휴가대장 관리용'!L40 -> 0 | I45: ='휴가대장 관리용'!M40 -> 0 | J45: ='휴가대장 관리용'!N40 -> 0 | K45: ='휴가대장 관리용'!O40 -> 0 | ... R45: ='휴가대장 관리용'!V40 -> 0
A46: 34 | B46: ='휴가대장 관리용'!C41 -> 0 | C46: ='휴가대장 관리용'!D41 -> - | D46: ='휴가대장 관리용'!H41 -> 0 | E46: ='휴가대장 관리용'!I41 -> 0 | F46: ='휴가대장 관리용'!J41 -> 0 | G46: ='휴가대장 관리용'!K41 -> 0 | H46: ='휴가대장 관리용'!L41 -> 0 | I46: ='휴가대장 관리용'!M41 -> 0 | J46: ='휴가대장 관리용'!N41 -> 0 | K46: ='휴가대장 관리용'!O41 -> 0 | ... R46: ='휴가대장 관리용'!V41 -> 0
A47: 35 | B47: ='휴가대장 관리용'!C42 -> 0 | C47: ='휴가대장 관리용'!D42 -> - | D47: ='휴가대장 관리용'!H42 -> 0 | E47: ='휴가대장 관리용'!I42 -> 0 | F47: ='휴가대장 관리용'!J42 -> 0 | G47: ='휴가대장 관리용'!K42 -> 0 | H47: ='휴가대장 관리용'!L42 -> 0 | I47: ='휴가대장 관리용'!M42 -> 0 | J47: ='휴가대장 관리용'!N42 -> 0 | K47: ='휴가대장 관리용'!O42 -> 0 | ... R47: ='휴가대장 관리용'!V42 -> 0
A48: 36 | B48: ='휴가대장 관리용'!C43 -> 0 | C48: ='휴가대장 관리용'!D43 -> - | D48: ='휴가대장 관리용'!H43 -> 0 | E48: ='휴가대장 관리용'!I43 -> 0 | F48: ='휴가대장 관리용'!J43 -> 0 | G48: ='휴가대장 관리용'!K43 -> 0 | H48: ='휴가대장 관리용'!L43 -> 0 | I48: ='휴가대장 관리용'!M43 -> 0 | J48: ='휴가대장 관리용'!N43 -> 0 | K48: ='휴가대장 관리용'!O43 -> 0 | ... R48: ='휴가대장 관리용'!V43 -> 0
A49: 37 | B49: ='휴가대장 관리용'!C44 -> 0 | C49: ='휴가대장 관리용'!D44 -> - | D49: ='휴가대장 관리용'!H44 -> 0 | E49: ='휴가대장 관리용'!I44 -> 0 | F49: ='휴가대장 관리용'!J44 -> 0 | G49: ='휴가대장 관리용'!K44 -> 0 | H49: ='휴가대장 관리용'!L44 -> 0 | I49: ='휴가대장 관리용'!M44 -> 0 | J49: ='휴가대장 관리용'!N44 -> 0 | K49: ='휴가대장 관리용'!O44 -> 0 | ... R49: ='휴가대장 관리용'!V44 -> 0
A50: 38 | B50: ='휴가대장 관리용'!C45 -> 0 | C50: ='휴가대장 관리용'!D45 -> - | D50: ='휴가대장 관리용'!H45 -> 0 | E50: ='휴가대장 관리용'!I45 -> 0 | F50: ='휴가대장 관리용'!J45 -> 0 | G50: ='휴가대장 관리용'!K45 -> 0 | H50: ='휴가대장 관리용'!L45 -> 0 | I50: ='휴가대장 관리용'!M45 -> 0 | J50: ='휴가대장 관리용'!N45 -> 0 | K50: ='휴가대장 관리용'!O45 -> 0 | ... R50: ='휴가대장 관리용'!V45 -> 0
A51: 39 | B51: ='휴가대장 관리용'!C46 -> 0 | C51: ='휴가대장 관리용'!D46 -> - | D51: ='휴가대장 관리용'!H46 -> 0 | E51: ='휴가대장 관리용'!I46 -> 0 | F51: ='휴가대장 관리용'!J46 -> 0 | G51: ='휴가대장 관리용'!K46 -> 0 | H51: ='휴가대장 관리용'!L46 -> 0 | I51: ='휴가대장 관리용'!M46 -> 0 | J51: ='휴가대장 관리용'!N46 -> 0 | K51: ='휴가대장 관리용'!O46 -> 0 | ... R51: ='휴가대장 관리용'!V46 -> 0
... A112: 100 | B112: ='휴가대장 관리용'!C107 -> 0 | C112: ='휴가대장 관리용'!D107 -> - | D112: ='휴가대장 관리용'!H107 -> 0 | E112: ='휴가대장 관리용'!I107 -> 0 | F112: ='휴가대장 관리용'!J107 -> 0 | G112: ='휴가대장 관리용'!K107 -> 0 | H112: ='휴가대장 관리용'!L107 -> 0 | I112: ='휴가대장 관리용'!M107 -> 0 | J112: ='휴가대장 관리용'!N107 -> 0 | K112: ='휴가대장 관리용'!O107 -> 0 | ... R112: ='휴가대장 관리용'!V107 -> 0

Sheet 관련정보
B9: * 연차휴가
B10: 1년에 80%이상 출근하면 15일의 연차유급휴가를 주어야 함.
B13: * 개정 연차휴가
B14: 1년미만일 때 최대 11일, 2년차일 때 15일연차휴가 사용가능하나,
B15: 5인미만사업장인지, 5인이상사업장인지 여부 및 사전에 상호합의 여부에 따라
B16: 사용가능여부가 달라지므로 관련기관에 반드시 문의하셔야 합니다.
B28: 출처 : 네이버, 지식백과 / 지식인

Sheet Sheet1 (2)
A1: 이름 | B1: 입사일 | C1: 연차일수
A2: 양승진 | B2: 1990-09-01 | C2: =IF(DATEDIF(B2, DATE(2025,1,1), "Y")<1, 0, MIN(15 + INT((DATEDIF(B2, DATE(2025,1,1), "Y") - 1) / 2), 25)) -> 25
A3: 최창열 | B3: 2000-10-01 | C3: =IF(DATEDIF(B3, DATE(2025,1,1), "Y")<1, 0, MIN(15 + INT((DATEDIF(B3, DATE(2025,1,1), "Y") - 1) / 2), 25)) -> 25
A4: 김은정 | B4: 2002-07-26 | C4: =IF(DATEDIF(B4, DATE(2025,1,1), "Y")<1, 0, MIN(15 + INT((DATEDIF(B4, DATE(2025,1,1), "Y") - 1) / 2), 25)) -> 25
A5: 이정화 | B5: 2003-01-02 | C5: =IF(DATEDIF(B5, DATE(2025,1,1), "Y")<1, 0, MIN(15 + INT((DATEDIF(B5, DATE(2025,1,1), "Y") - 1) / 2), 25)) -> 25
A6: 하치복 | B6: 2004-03-15 | C6: =IF(DATEDIF(B6, DATE(2025,1,1), "Y")<1, 0, MIN(15 + INT((DATEDIF(B6, DATE(2025,1,1), "Y") - 1) / 2), 25)) -> 24
A7: 권혁진 | B7: 2004-11-10 | C7: =IF(DATEDIF(B7, DATE(2025,1,1), "Y")<1, 0, MIN(15 + INT((DATEDIF(B7, DATE(2025,1,1), "Y") - 1) / 2), 25)) -> 24
A8: 김경태 | B8: 2013-04-26 | C8: =IF(DATEDIF(B8, DATE(2025,1,1), "Y")<1, 0, MIN(15 + INT((DATEDIF(B8, DATE(2025,1,1), "Y") - 1) / 2), 25)) -> 20
A9: 조근일 | B9: 2013-11-04 | C9: =IF(DATEDIF(B9, DATE(2025,1,1), "Y")<1, 0, MIN(15 + INT((DATEDIF(B9, DATE(2025,1,1), "Y") - 1) / 2), 25)) -> 20
A10: 이재형 | B10: 2015-03-16 | C10: =IF(DATEDIF(B10, DATE(2025,1,1), "Y")<1, 0, MIN(15 + INT((DATEDIF(B10, DATE(2025,1,1), "Y") - 1) / 2), 25)) -> 19
A11: 임소연 | B11: 2006-12-01 | C11: =IF(DATEDIF(B11, DATE(2025,1,1), "Y")<1, 0, MIN(15 + INT((DATEDIF(B11, DATE(2025,1,1), "Y") - 1) / 2), 25)) -> 23
A12: 김지혜 | B12: 2018-02-06 | C12: =IF(DATEDIF(B12, DATE(2025,1,1), "Y")<1, 0, MIN(15 + INT((DATEDIF(B12, DATE(2025,1,1), "Y") - 1) / 2), 25)) -> 17
A13: 정승후 | B13: 2018-07-02 | C13: =IF(DATEDIF(B13, DATE(2025,1,1), "Y")<1, 0, MIN(15 + INT((DATEDIF(B13, DATE(2025,1,1), "Y") - 1) / 2), 25)) -> 17
... A17: 김희승 | B17: 2018-09-03 | C17: =IF(DATEDIF(B17, DATE(2025,1,1), "Y")<1, 0, MIN(15 + INT((DATEDIF(B17, DATE(2025,1,1), "Y") - 1) / 2), 25)) -> 17
A18: 곽병현 | B18: 2019-04-08 | C18: =IF(DATEDIF(B18, DATE(2025,1,1), "Y")<1, 0, MIN(15 + INT((DATEDIF(B18, DATE(2025,1,1), "Y") - 1) / 2), 25)) -> 17 | Q18: 강영은 | R18: 15
A19: 윤은호 | B19: 2019-07-01 | C19: =IF(DATEDIF(B19, DATE(2025,1,1), "Y")<1, 0, MIN(15 + INT((DATEDIF(B19, DATE(2025,1,1), "Y") - 1) / 2), 25)) -> 17 | Q19: 곽병현 | R19: 18
A20: 김윤회 | B20: 2019-11-02 | C20: =IF(DATEDIF(B20, DATE(2025,1,1), "Y")<1, 0, MIN(15 + INT((DATEDIF(B20, DATE(2025,1,1), "Y") - 1) / 2), 25)) -> 17 | Q20: 권혁진 | R20: 25
A21: 석진태 | B21: 2022-03-21 | C21: =IF(DATEDIF(B21, DATE(2025,1,1), "Y")<1, 0, MIN(15 + INT((DATEDIF(B21, DATE(2025,1,1), "Y") - 1) / 2), 25)) -> 15 | Q21: 김경태 | R21: 20
A22: 여도근 | B22: 2022-04-01 | C22: =IF(DATEDIF(B22, DATE(2025,1,1), "Y")<1, 0, MIN(15 + INT((DATEDIF(B22, DATE(2025,1,1), "Y") - 1) / 2), 25)) -> 15 | H22: 25년6월24일 기준 | Q22: 김윤회 | R22: 18
A23: 강영은 | B23: 2022-08-03 | C23: =IF(DATEDIF(B23, DATE(2025,1,1), "Y")<1, 0, MIN(15 + INT((DATEDIF(B23, DATE(2025,1,1), "Y") - 1) / 2), 25)) -> 15 | Q23: 김은정 | R23: 25
A24: 이한빈 | B24: 2023-01-01 | C24: =IF(DATEDIF(B24, DATE(2025,1,1), "Y")<1, 0, MIN(15 + INT((DATEDIF(B24, DATE(2025,1,1), "Y") - 1) / 2), 25)) -> 15 | F24: 여도근 | G24: 2022-04-01 | H24: 8일 | Q24: 김지혜 | R24: 17
G25: 44927 | H25: 15 | I25: 1년
G26: 45292 | H26: 15 | I26: 2년
G27: 45658 | H27: 15 | I27: 3년
G28: 46023 | H28: 16 | I28: 4년
A29: 백현덕 | B29: 2023-03-06 | C29: =IF(DATEDIF(B29, DATE(2025,1,1), "Y")<1, 0, MIN(15 + INT((DATEDIF(B29, DATE(2025,1,1), "Y") - 1) / 2), 25)) -> 15 | F29: 강영은 | G29: 2022-08-03 | H29: 15 | Q29: 김희승 | R29: 17
A30: 이종근 | B30: 45586 | C30: =IF(DATEDIF(B30, DATE(2025,1,1), "Y")<1, 0, MIN(15 + INT((DATEDIF(B30, DATE(2025,1,1), "Y") - 1) / 2), 25)) -> 0 | F30: 이한빈 | G30: 2023-01-01 | H30: 15 | Q30: 나유성 | R30: 17
A31: 이채령 | B31: 45663 | C31: 0 | F31: 백현덕 | G31: 2023-03-06 | H31: 15 | Q31: 백현덕 | R31: 15
F32: 이종근 | G32: 45586 | H32: 2 | Q32: 석진태 | R32: 15
G33: 45658 | H33: 15 | I33: 1년 | Q33: 양승진 | R33: 25
G34: 46023 | H34: 15 | I34: 2년 | Q34: 여도근 | R34: 15
G35: 46388 | H35: 15 | I35: 3년 | Q35: 윤은호 | R35: 18
G36: 46753 | H36: 16 | I36: 4년 | Q36: 이재형 | R36: 19
Q37: 이정화 | R37: 25
Q38: 이종근 | R38: 15
Q39: 이채령 | R39: 11
Q40: 이한빈 | R40: 15
Q41: 임소연 | R41: 23
Q42: 정승후 | R42: 17
Q43: 정현웅 | R43: 17
...
